Workbook
Name aaa: Rank!$C$4:$E$73
Name bbb: Rank!$B$4:$E$74
Name China1: #REF!
Name cnfwkdn: #REF!
Name DB: #REF!
Name dpfwlf: #REF!
Name ggoo: #REF!
Name gogo: #REF!
Name gogogo: #REF!
Name gogogogo: #REF!
Name LGE: #REF!
Name MS: #REF!
Name MS: #REF!
Name Pantech: #REF!
Name totototo: #REF!
Name 엘지: #REF!
Name 전자소자: #REF!
Name 전자소자: #REF!
Name 정기어소: #REF!
Name 중국: #REF!
Name 팬택: #REF!

Sheet New Graph (FCST)
A2: A. | B2: 2021 REVENUE (FORECAST)
A4: A.1 | B4: 2021 Monthly Forecast
B5: ※ Q'ty: total quanitity (including wafer net die, controller & others)
B6: - | C6: Jan | E6: Feb | G6: Mar | I6: Apr | K6: May | M6: Jun | O6: Jul | Q6: Aug | S6: Sep | U6: Oct | W6: Nov | Y6: Dec | AA6: Total
C7: Q'ty | D7: AMT | E7: Q'ty | F7: AMT | G7: Q'ty | H7: AMT | I7: Q'ty | J7: AMT | K7: Q'ty | L7: AMT | M7: Q'ty | N7: AMT | O7: Q'ty | P7: AMT | Q7: Q'ty | R7: AMT | S7: Q'ty | T7: AMT | U7: Q'ty | V7: AMT | W7: Q'ty | X7: AMT | Y7: Q'ty | Z7: AMT | AA7: Q'ty | AB7: AMT
B8: MD | C8: ='2025 FCST'!G510 -> 3.821 | D8: ='2025 FCST'!I464 -> 149.7255 | E8: ='2025 FCST'!P510 -> 0.435 | F8: ='2025 FCST'!R464 -> 435.14552 | G8: ='2025 FCST'!Y510 -> 5.839 | H8: ='2025 FCST'!AA464 -> 431.58985 | I8: ='2025 FCST'!AQ510 -> 6.025 | J8: ='2025 FCST'!AS464 -> 2781.69 | K8: ='2025 FCST'!AZ510 -> 5.905 | L8: ='2025 FCST'!BB464 -> 1549.85 | M8: ='2025 FCST'!BI510 -> 11.5594 | N8: ='2025 FCST'!BK464 -> 659.12596 | O8: ='2025 FCST'!CA510 -> 40.6175 | P8: ='2025 FCST'!CC464 -> 931.9 | Q8: ='2025 FCST'!CJ510 -> 9.697 | R8: ='2025 FCST'!CL464 -> 546.31 | S8: ='2025 FCST'!CS510 -> 15.305 | T8: ='2025 FCST'!CU464 -> 1667.45 | U8: ='2025 FCST'!DK510 -> 16.405 | V8: ='2025 FCST'!DM464 -> 1419.15 | W8: ='2025 FCST'!DT510 -> 13.197 | X8: ='2025 FCST'!DV464 -> 779.16 | Y8: ='2025 FCST'!EC510 -> 21.305 | Z8: ='2025 FCST'!EE464 -> 1040.1 | AA8: =SUM(C8+E8+G8+I8+K8+M8+O8+Q8+S8+U8+W8+Y8) -> 150.1109 | AB8: =D8+F8+H8+J8+L8+N8+P8+R8+T8+V8+X8+Z8 -> 12391.197
B9: MTV | C9: ='2025 FCST'!G514 -> 60 | D9: ='2025 FCST'!I99 -> 24.5 | E9: ='2025 FCST'!P514 -> 60 | F9: ='2025 FCST'!R99 -> 59.22 | G9: ='2025 FCST'!Y514 -> 149.501 | H9: ='2025 FCST'!AA99 -> 35.7139 | I9: ='2025 FCST'!AQ514 -> 130 | J9: ='2025 FCST'!AS99 -> 96.46 | K9: ='2025 FCST'!AZ514 -> 80 | L9: ='2025 FCST'!BB99 -> 78.96 | M9: ='2025 FCST'!BI514 -> 277.501 | N9: ='2025 FCST'!BK99 -> 156.8619 | O9: ='2025 FCST'!CA514 -> 80 | P9: ='2025 FCST'!CC99 -> 78.96 | Q9: ='2025 FCST'!CJ514 -> 229.501 | R9: ='2025 FCST'!CL99 -> 114.6739 | S9: ='2025 FCST'!CS514 -> 90 | T9: ='2025 FCST'!CU99 -> 85.96 | U9: ='2025 FCST'!DK514 -> 130 | V9: ='2025 FCST'!DM99 -> 96.46 | W9: ='2025 FCST'!DT514 -> 80 | X9: ='2025 FCST'!DV99 -> 78.96 | Y9: ='2025 FCST'!EC514 -> 130 | Z9: ='2025 FCST'!EE99 -> 123 | AA9: =SUM(C9+E9+G9+I9+K9+M9+O9+Q9+S9+U9+W9+Y9) -> 1496.503 | AB9: =D9+F9+H9+J9+L9+N9+P9+R9+T9+V9+X9+Z9 -> 1029.7297
B10: Total | C10: =C8+C9 -> 63.821 | D10: =D8+D9 -> 174.2255 | E10: =E8+E9 -> 60.435 | F10: =F8+F9 -> 494.36552 | G10: =G8+G9 -> 155.34 | H10: =H8+H9 -> 467.30375 | I10: =I8+I9 -> 136.025 | J10: =J8+J9 -> 2878.15 | ... AB10: =AB8+AB9 -> 13420.927
AB11: (unit: kpcs, k$)
B13: 2021 Total Revenue/Month
B29: - | C29: Jan | D29: Feb | E29: Mar | F29: Apr | G29: May | H29: Jun | I29: Jul | J29: Aug | K29: Sep | L29: Oct | M29: Nov | N29: Dec | O29: Total
B30: MD | C30: =D8 -> 149.7255 | D30: =F8 -> 435.14552 | E30: =H8 -> 431.58985 | F30: =J8 -> 2781.69 | G30: =L8 -> 1549.85 | H30: =N8 -> 659.12596 | I30: =P8 -> 931.9 | J30: =R8 -> 546.31 | K30: =T8 -> 1667.45 | L30: =V8 -> 1419.15 | M30: =X8 -> 779.16 | N30: =Z8 -> 1040.1 | O30: =SUM(C30:N30) -> 12391.197
B31: MTV | C31: =D9 -> 24.5 | D31: =F9 -> 59.22 | E31: =H9 -> 35.7139 | F31: =J9 -> 96.46 | G31: =L9 -> 78.96 | H31: =N9 -> 156.8619 | I31: =P9 -> 78.96 | J31: =R9 -> 114.6739 | K31: =T9 -> 85.96 | L31: =V9 -> 96.46 | M31: =X9 -> 78.96 | N31: =Z9 -> 123 | O31: =SUM(C31:N31) -> 1029.7297
B32: Total | C32: =C30+C31 -> 174.2255 | D32: =D30+D31 -> 494.36552 | E32: =E30+E31 -> 467.30375 | F32: =F30+F31 -> 2878.15 | G32: =G30+G31 -> 1628.81 | H32: =H30+H31 -> 815.98786 | I32: =I30+I31 -> 1010.86 | J32: =J30+J31 -> 660.9839 | ... N32: =N30+N31 -> 1163.1 | O32: =SUM(C32:N32) -> 13420.927
O33: (unit: k$)
B35: 2021 Microdisplay - Total Quantity/Month | Q35: 2021 Microdisplay - Revenue/Month
B45: - | C45: Jan | D45: Feb | E45: Mar | F45: Apr | G45: May | H45: Jun | I45: Jul | J45: Aug | K45: Sep | L45: Oct | M45: Nov | N45: Dec | O45: Total | Q45: - | R45: Jan | S45: Feb. | T45: Mar | U45: Apr | V45: May | W45: Jun | X45: Jul | Y45: Aug | Z45: Sep | AA45: Oct | AB45: Nov | AC45: Dec | AD45: Total
B46: MD | C46: =C8 -> 3.821 | D46: =E8 -> 0.435 | E46: =G8 -> 5.839 | F46: =I8 -> 6.025 | G46: =K8 -> 5.905 | H46: =M8 -> 11.5594 | I46: =O8 -> 40.6175 | J46: =Q8 -> 9.697 | K46: =S8 -> 15.305 | L46: =U8 -> 16.405 | M46: =W8 -> 13.197 | N46: =Y8 -> 21.305 | O46: =SUM(C46:N46) -> 150.1109 | Q46: MD | R46: =D8 -> 149.7255 | S46: =F8 -> 435.14552 | T46: =H8 -> 431.58985 | U46: =J8 -> 2781.69 | V46: =L8 -> 1549.85 | W46: =N8 -> 659.12596 | X46: =P8 -> 931.9 | Y46: =R8 -> 546.31 | Z46: =T8 -> 1667.45 | AA46: =V8 -> 1419.15 | AB46: =X8 -> 779.16 | AC46: =Z8 -> 1040.1 | AD46: =SUM(R46:AC46) -> 12391.197
O47: (unit: kpcs) | AD47: (unit: k$)
B49: 2021 Microdisplay - Display Quantity/Month
B50: ※ Display Quantity: Panel + Optic + Panel wafer net die
B60: - | C60: Jan | D60: Feb | E60: Mar | F60: Apr | G60: May | H60: Jun | I60: Jul | J60: Aug | K60: Sep | L60: Oct | M60: Nov | N60: Dec | O60: Total
B61: Display | C61: ='2025 FCST'!G518 -> 2.517 | D61: ='2025 FCST'!P518 -> 0.257 | E61: ='2025 FCST'!Y518 -> 5.694 | F61: ='2025 FCST'!AQ518 -> 4.4 | G61: ='2025 FCST'!AZ518 -> 4.4 | H61: ='2025 FCST'!BI518 -> 7.6544 | I61: ='2025 FCST'!CA518 -> 37.5125 | J61: ='2025 FCST'!CJ518 -> 6.792 | K61: ='2025 FCST'!CS518 -> 10.2 | L61: ='2025 FCST'!DK518 -> 7.5 | M61: ='2025 FCST'!DT518 -> 6.792 | N61: ='2025 FCST'!EC518 -> 12.1 | O61: =SUM(C61:N61) -> 105.8189
O62: (unit: kpcs)
B64: 2021 MTV - Total Quantity/Month | Q64: 2021 MTV - Revenue/Month
B74: - | C74: Jan | D74: Feb | E74: Mar | F74: Apr | G74: May | H74: Jun | I74: Jul | J74: Aug | K74: Sep | L74: Oct | M74: Nov | N74: Dec | O74: Total | Q74: - | R74: Jan | S74: Feb. | T74: Mar | U74: Apr | V74: May | W74: Jun | X74: Jul | Y74: Aug | Z74: Sep | AA74: Oct | AB74: Nov | AC74: Dec | AD74: Total
B75: MTV | C75: =C9 -> 60 | D75: =E9 -> 60 | E75: =G9 -> 149.501 | F75: =I9 -> 130 | G75: =K9 -> 80 | H75: =M9 -> 277.501 | I75: =O9 -> 80 | J75: =Q9 -> 229.501 | K75: =S9 -> 90 | L75: =U9 -> 130 | M75: =W9 -> 80 | N75: =Y9 -> 130 | O75: =SUM(C75:N75) -> 1496.503 | Q75: MTV | R75: =D9 -> 24.5 | S75: =F9 -> 59.22 | T75: =H9 -> 35.7139 | U75: =J9 -> 96.46 | V75: =L9 -> 78.96 | W75: =N9 -> 156.8619 | X75: =P9 -> 78.96 | Y75: =R9 -> 114.6739 | Z75: =T9 -> 85.96 | AA75: =V9 -> 96.46 | AB75: =X9 -> 78.96 | AC75: =Z9 -> 123 | AD75: =SUM(R75:AC75) -> 1029.7297
O76: (unit: kpcs) | AD76: (unit: k$)
A79: A.2 | B79: 2021 Quarterly Forecast
B81: - | C81: Q1 | E81: Q2 | G81: Q3 | I81: Q4 | K81: Total
C82: Q'ty | D82: AMT | E82: Q'ty | F82: AMT | G82: Q'ty | H82: AMT | I82: Q'ty | J82: AMT | K82: Q'ty | L82: AMT
B83: MD | C83: =C46+D46+E46 -> 10.095 | D83: ='2025 FCST'!AJ464 -> 957.61687 | E83: =F46+G46+H46 -> 23.4894 | F83: ='2025 FCST'!BT464 -> 4974.916 | G83: =I46+J46+K46 -> 65.6195 | H83: ='2025 FCST'!DD464 -> 3145.66 | I83: =L46+M46+N46 -> 50.907 | J83: ='2025 FCST'!EN464 -> 3222.66 | K83: =C83+E83+G83+I83 -> 150.1109 | L83: =D83+F83+H83+J83 -> 12300.853
B84: MTV | C84: =C75+D75+E75 -> 269.501 | D84: ='2025 FCST'!AJ99 -> 119.4339 | E84: =F75+G75+H75 -> 487.501 | F84: ='2025 FCST'!BT99 -> 332.2819 | G84: =I75+J75+K75 -> 399.501 | H84: ='2025 FCST'!DD99 -> 279.5939 | I84: =L75+M75+N75 -> 340 | J84: ='2025 FCST'!EN99 -> 298.42 | K84: =C84+E84+G84+I84 -> 1496.503 | L84: =D84+F84+H84+J84 -> 1029.7297
B85: Total | C85: =C83+C84 -> 279.596 | D85: =D83+D84 -> 1077.0508 | E85: =E83+E84 -> 510.9904 | F85: =F83+F84 -> 5307.1979 | G85: =G83+G84 -> 465.1205 | H85: =H83+H84 -> 3425.2539 | I85: =I83+I84 -> 390.907 | J85: =J83+J84 -> 3521.08 | ... L85: =L83+L84 -> 13330.583
L86: (unit: kpcs, k$)
B88: 2021 Microdisplay - Total Quantity/Quarter | I88: 2021 Microdisplay - Revenue/Quarter
B98: - | C98: Q1 | D98: Q2 | E98: Q3 | F98: Q4 | G98: Total | I98: - | J98: Q1 | K98: Q2 | L98: Q3 | M98: Q4 | N98: Total
B99: MD | C99: =C83 -> 10.095 | D99: =E83 -> 23.4894 | E99: =G83 -> 65.6195 | F99: =I83 -> 50.907 | G99: =SUM(C99:F99) -> 150.1109 | I99: MD | J99: =D83 -> 957.61687 | K99: =F83 -> 4974.916 | L99: =H83 -> 3145.66 | M99: =J83 -> 3222.66 | N99: =SUM(J99:M99) -> 12300.853
G100: (unit: kpcs) | N100: (unit: k$)
B102: 2021 Microdisplay - Display Quantity/Quarter
...

Sheet New Graph (PLAN)
A2: A. | B2: 2021 REVENUE (PLAN)
A4: A.1 | B4: 2021 Monthly Plan
B5: ※ Q'ty: total quanitity (including wafer net die, controller & others)
B6: - | C6: Jan | E6: Feb | G6: Mar | I6: Apr | K6: May | M6: Jun | O6: Jul | Q6: Aug | S6: Sep | U6: Oct | W6: Nov | Y6: Dec | AA6: Total
C7: Q'ty | D7: AMT | E7: Q'ty | F7: AMT | G7: Q'ty | H7: AMT | I7: Q'ty | J7: AMT | K7: Q'ty | L7: AMT | M7: Q'ty | N7: AMT | O7: Q'ty | P7: AMT | Q7: Q'ty | R7: AMT | S7: Q'ty | T7: AMT | U7: Q'ty | V7: AMT | W7: Q'ty | X7: AMT | Y7: Q'ty | Z7: AMT | AA7: Q'ty | AB7: AMT
B8: MD | C8: ='2025 FCST'!J510 -> 4.116 | D8: ='2025 FCST'!I464 -> 149.7255 | E8: ='2025 FCST'!S510 -> 5.6574 | F8: ='2025 FCST'!R464 -> 435.14552 | G8: ='2025 FCST'!AB510 -> 16.235 | H8: ='2025 FCST'!AA464 -> 431.58985 | I8: ='2025 FCST'!AT510 -> 11.905 | J8: ='2025 FCST'!AV464 -> 2436.5 | K8: ='2025 FCST'!BC510 -> 14.005 | L8: ='2025 FCST'!BE464 -> 2033.3 | M8: ='2025 FCST'!BL510 -> 20.497 | N8: ='2025 FCST'!BN464 -> 971.06 | O8: ='2025 FCST'!CD510 -> 69.2225 | P8: ='2025 FCST'!CF464 -> 1479.25 | Q8: ='2025 FCST'!CM510 -> 24.733 | R8: ='2025 FCST'!CO464 -> 868.44 | S8: ='2025 FCST'!CV510 -> 45.285 | T8: ='2025 FCST'!CX464 -> 2933.35 | U8: ='2025 FCST'!DN510 -> 19.705 | V8: ='2025 FCST'!DP464 -> 1787.8 | W8: ='2025 FCST'!DW510 -> 18.897 | X8: ='2025 FCST'!DY464 -> 885.96 | Y8: ='2025 FCST'!EF510 -> 31.615 | Z8: ='2025 FCST'!EH464 -> 1221.3 | AA8: =SUM(C8+E8+G8+I8+K8+M8+O8+Q8+S8+U8+W8+Y8) -> 281.8729 | AB8: =D8+F8+H8+J8+L8+N8+P8+R8+T8+V8+X8+Z8 -> 15633.421
B9: MTV | C9: ='2025 FCST'!J514 -> 60 | D9: ='2025 FCST'!I99 -> 24.5 | E9: ='2025 FCST'!S514 -> 249.501 | F9: ='2025 FCST'!R99 -> 59.22 | G9: ='2025 FCST'!AB514 -> 100 | H9: ='2025 FCST'!AA99 -> 35.7139 | I9: ='2025 FCST'!AT514 -> 249.501 | J9: ='2025 FCST'!AV99 -> 134.4139 | K9: ='2025 FCST'!BC514 -> 275 | L9: ='2025 FCST'!BE99 -> 276.5 | M9: ='2025 FCST'!BL514 -> 401.501 | N9: ='2025 FCST'!BN99 -> 272.9059 | O9: ='2025 FCST'!CD514 -> 150 | P9: ='2025 FCST'!CF99 -> 116.2 | Q9: ='2025 FCST'!CM514 -> 249.501 | R9: ='2025 FCST'!CO99 -> 134.4139 | S9: ='2025 FCST'!CV514 -> 285 | T9: ='2025 FCST'!CX99 -> 283.5 | U9: ='2025 FCST'!DN514 -> 399.002 | V9: ='2025 FCST'!DP99 -> 170.1278 | W9: ='2025 FCST'!DW514 -> 100 | X9: ='2025 FCST'!DY99 -> 98.7 | Y9: ='2025 FCST'!EF514 -> 285 | Z9: ='2025 FCST'!EH99 -> 283.5 | AA9: =SUM(C9+E9+G9+I9+K9+M9+O9+Q9+S9+U9+W9+Y9) -> 2804.006 | AB9: =D9+F9+H9+J9+L9+N9+P9+R9+T9+V9+X9+Z9 -> 1889.6954
B10: Total | C10: =C8+C9 -> 64.116 | D10: =D8+D9 -> 174.2255 | E10: =E8+E9 -> 255.1584 | F10: =F8+F9 -> 494.36552 | G10: =G8+G9 -> 116.235 | H10: =H8+H9 -> 467.30375 | I10: =I8+I9 -> 261.406 | J10: =J8+J9 -> 2570.9139 | ... AB10: =AB8+AB9 -> 17523.116
AB11: (unit: kpcs, k$)
B13: 2021 Total Revenue/Month
B29: - | C29: Jan | D29: Feb | E29: Mar | F29: Apr | G29: May | H29: Jun | I29: Jul | J29: Aug | K29: Sep | L29: Oct | M29: Nov | N29: Dec | O29: Total
B30: MD | C30: =D8 -> 149.7255 | D30: =F8 -> 435.14552 | E30: =H8 -> 431.58985 | F30: =J8 -> 2436.5 | G30: =L8 -> 2033.3 | H30: =N8 -> 971.06 | I30: =P8 -> 1479.25 | J30: =R8 -> 868.44 | K30: =T8 -> 2933.35 | L30: =V8 -> 1787.8 | M30: =X8 -> 885.96 | N30: =Z8 -> 1221.3 | O30: =SUM(C30:N30) -> 15633.421
B31: MTV | C31: =D9 -> 24.5 | D31: =F9 -> 59.22 | E31: =H9 -> 35.7139 | F31: =J9 -> 134.4139 | G31: =L9 -> 276.5 | H31: =N9 -> 272.9059 | I31: =P9 -> 116.2 | J31: =R9 -> 134.4139 | K31: =T9 -> 283.5 | L31: =V9 -> 170.1278 | M31: =X9 -> 98.7 | N31: =Z9 -> 283.5 | O31: =SUM(C31:N31) -> 1889.6954
B32: Total | C32: =C30+C31 -> 174.2255 | D32: =D30+D31 -> 494.36552 | E32: =E30+E31 -> 467.30375 | F32: =F30+F31 -> 2570.9139 | G32: =G30+G31 -> 2309.8 | H32: =H30+H31 -> 1243.9659 | I32: =I30+I31 -> 1595.45 | J32: =J30+J31 -> 1002.8539 | ... N32: =N30+N31 -> 1504.8 | O32: =SUM(C32:N32) -> 17523.116
O33: (unit: k$)
B35: 2021 Microdisplay - Total Quantity/Month | Q35: 2021 Microdisplay - Revenue/Month
B45: - | C45: Jan | D45: Feb | E45: Mar | F45: Apr | G45: May | H45: Jun | I45: Jul | J45: Aug | K45: Sep | L45: Oct | M45: Nov | N45: Dec | O45: Total | Q45: - | R45: Jan | S45: Feb. | T45: Mar | U45: Apr | V45: May | W45: Jun | X45: Jul | Y45: Aug | Z45: Sep | AA45: Oct | AB45: Nov | AC45: Dec | AD45: Total
B46: MD | C46: =C8 -> 4.116 | D46: =E8 -> 5.6574 | E46: =G8 -> 16.235 | F46: =I8 -> 11.905 | G46: =K8 -> 14.005 | H46: =M8 -> 20.497 | I46: =O8 -> 69.2225 | J46: =Q8 -> 24.733 | K46: =S8 -> 45.285 | L46: =U8 -> 19.705 | M46: =W8 -> 18.897 | N46: =Y8 -> 31.615 | O46: =SUM(C46:N46) -> 281.8729 | Q46: MD | R46: =D8 -> 149.7255 | S46: =F8 -> 435.14552 | T46: =H8 -> 431.58985 | U46: =J8 -> 2436.5 | V46: =L8 -> 2033.3 | W46: =N8 -> 971.06 | X46: =P8 -> 1479.25 | Y46: =R8 -> 868.44 | Z46: =T8 -> 2933.35 | AA46: =V8 -> 1787.8 | AB46: =X8 -> 885.96 | AC46: =Z8 -> 1221.3 | AD46: =SUM(R46:AC46) -> 15633.421
O47: (unit: kpcs) | AD47: (unit: k$)
B49: 2021 Microdisplay - Display Quantity/Month
B50: ※ Display Quantity: Panel + Optic + Panel wafer net die
B60: - | C60: Jan | D60: Feb | E60: Mar | F60: Apr | G60: May | H60: Jun | I60: Jul | J60: Aug | K60: Sep | L60: Oct | M60: Nov | N60: Dec | O60: Total
B61: Display | C61: ='2025 FCST'!J518 -> 2.911 | D61: ='2025 FCST'!S518 -> 4.2624 | E61: ='2025 FCST'!AB518 -> 11.5 | F61: ='2025 FCST'!AT518 -> 8.8 | G61: ='2025 FCST'!BC518 -> 10.6 | H61: ='2025 FCST'!BL518 -> 11.492 | I61: ='2025 FCST'!CD518 -> 46.5175 | J61: ='2025 FCST'!CM518 -> 11.428 | K61: ='2025 FCST'!CV518 -> 31.48 | L61: ='2025 FCST'!DN518 -> 11.6 | M61: ='2025 FCST'!DW518 -> 15.292 | N61: ='2025 FCST'!EF518 -> 24.51 | O61: =SUM(C61:N61) -> 190.3929
O62: (unit: kpcs)
B64: 2021 MTV - Total Quantity/Month | Q64: 2021 MTV - Revenue/Month
B74: - | C74: Jan | D74: Feb | E74: Mar | F74: Apr | G74: May | H74: Jun | I74: Jul | J74: Aug | K74: Sep | L74: Oct | M74: Nov | N74: Dec | O74: Total | Q74: - | R74: Jan | S74: Feb. | T74: Mar | U74: Apr | V74: May | W74: Jun | X74: Jul | Y74: Aug | Z74: Sep | AA74: Oct | AB74: Nov | AC74: Dec | AD74: Total
B75: MD | C75: =C9 -> 60 | D75: =E9 -> 249.501 | E75: =G9 -> 100 | F75: =I9 -> 249.501 | G75: =K9 -> 275 | H75: =M9 -> 401.501 | I75: =O9 -> 150 | J75: =Q9 -> 249.501 | K75: =S9 -> 285 | L75: =U9 -> 399.002 | M75: =W9 -> 100 | N75: =Y9 -> 285 | O75: =SUM(C75:N75) -> 2804.006 | Q75: MD | R75: =D9 -> 24.5 | S75: =F9 -> 59.22 | T75: =H9 -> 35.7139 | U75: =J9 -> 134.4139 | V75: =L9 -> 276.5 | W75: =N9 -> 272.9059 | X75: =P9 -> 116.2 | Y75: =R9 -> 134.4139 | Z75: =T9 -> 283.5 | AA75: =V9 -> 170.1278 | AB75: =X9 -> 98.7 | AC75: =Z9 -> 283.5 | AD75: =SUM(R75:AC75) -> 1889.6954
O76: (unit: kpcs) | AD76: (unit: k$)
A79: A.2 | B79: 2021 Quarterly Plan | Q79: 2022 Quarterly Plan
B81: - | C81: Q1 | E81: Q2 | G81: Q3 | I81: Q4 | K81: Total | Q81: - | R81: Q1 | T81: Q2 | V81: Q3 | X81: Q4 | Z81: Total
C82: Q'ty | D82: AMT | E82: Q'ty | F82: AMT | G82: Q'ty | H82: AMT | I82: Q'ty | J82: AMT | K82: Q'ty | L82: AMT | R82: Q'ty | S82: AMT | T82: Q'ty | U82: AMT | V82: Q'ty | W82: AMT | X82: Q'ty | Y82: AMT | Z82: Q'ty | AA82: AMT
B83: MD | C83: =C46+D46+E46 -> 26.0084 | D83: ='2025 FCST'!AJ464 -> 957.61687 | E83: =F46+G46+H46 -> 46.407 | F83: ='2025 FCST'!BW464 -> 5440.86 | G83: =I46+J46+K46 -> 139.2405 | H83: ='2025 FCST'!DG464 -> 5281.04 | I83: =L46+M46+N46 -> 70.217 | J83: ='2025 FCST'!EQ464 -> 3863.56 | K83: =C83+E83+G83+I83 -> 281.8729 | L83: =D83+F83+H83+J83 -> 15543.077 | Q83: MD | R83: ='2025 FCST'!GM464 -> 17.657 | S83: ='2025 FCST'!GO464 -> 4027.92 | T83: ='2025 FCST'!HW464 -> 40.085 | U83: ='2025 FCST'!HY464 -> 2466.1 | V83: ='2025 FCST'!JG464 -> 101.268 | W83: ='2025 FCST'!JI464 -> 4065.99 | X83: ='2025 FCST'!KQ464 -> 24.415 | Y83: ='2025 FCST'!KS464 -> 1082 | Z83: =R83+T83+V83+X83 -> 183.425 | AA83: =S83+U83+W83+Y83 -> 11642.01
B84: MTV | C84: =C75+D75+E75 -> 409.501 | D84: ='2025 FCST'!AJ99 -> 119.4339 | E84: =F75+G75+H75 -> 926.002 | F84: ='2025 FCST'!BW99 -> 683.8198 | G84: =I75+J75+K75 -> 684.501 | H84: ='2025 FCST'!DG99 -> 534.1139 | I84: =L75+M75+N75 -> 784.002 | J84: ='2025 FCST'!EQ99 -> 552.3278 | K84: =C84+E84+G84+I84 -> 2804.006 | L84: =D84+F84+H84+J84 -> 1889.6954 | Q84: MTV | R84: ='2025 FCST'!GM99 -> 409.501 | S84: ='2025 FCST'!GO99 -> 257.6139 | T84: ='2025 FCST'!HW99 -> 926.002 | U84: ='2025 FCST'!HY99 -> 683.8198 | V84: ='2025 FCST'!JG99 -> 684.501 | W84: ='2025 FCST'!JI99 -> 534.1139 | X84: ='2025 FCST'!KQ99 -> 784.002 | Y84: ='2025 FCST'!KS99 -> 552.3278 | Z84: =R84+T84+V84+X84 -> 2804.006 | AA84: =S84+U84+W84+Y84 -> 2027.8754
B85: Total | C85: =C83+C84 -> 435.5094 | D85: =D83+D84 -> 1077.0508 | E85: =E83+E84 -> 972.409 | F85: =F83+F84 -> 6124.6798 | G85: =G83+G84 -> 823.7415 | H85: =H83+H84 -> 5815.1539 | I85: =I83+I84 -> 854.219 | J85: =J83+J84 -> 4415.8878 | ... L85: =L83+L84 -> 17432.772 | Q85: Total | R85: =R83+R84 -> 427.158 | S85: =S83+S84 -> 4285.5339 | T85: =T83+T84 -> 966.087 | U85: =U83+U84 -> 3149.9198 | V85: =V83+V84 -> 785.769 | W85: =W83+W84 -> 4600.1039 | X85: =X83+X84 -> 808.417 | Y85: =Y83+Y84 -> 1634.3278 | ... AA85: =AA83+AA84 -> 13669.885
L86: (unit: kpcs, k$) | AA86: (unit: kpcs, k$)
B88: 2021 Microdisplay - Total Quantity/Quarter | I88: 2021 Microdisplay - Revenue/Quarter
B98: - | C98: Q1 | D98: Q2 | E98: Q3 | F98: Q4 | G98: Total | I98: - | J98: Q1 | K98: Q2 | L98: Q3 | M98: Q4 | N98: Total | X98: - | Y98: Q1 | Z98: Q2 | AA98: Q3 | AB98: Q4 | AC98: Total
B99: MD | C99: =C83 -> 26.0084 | D99: =E83 -> 46.407 | E99: =G83 -> 139.2405 | F99: =I83 -> 70.217 | G99: =SUM(C99:F99) -> 281.8729 | I99: MD | J99: =D83 -> 957.61687 | K99: =F83 -> 5440.86 | L99: =H83 -> 5281.04 | M99: =J83 -> 3863.56 | N99: =SUM(J99:M99) -> 15543.077 | X99: MD | Y99: =S83 -> 4027.92 | Z99: =U83 -> 2466.1 | AA99: =W83 -> 4065.99 | AB99: =Y83 -> 1082 | AC99: =SUM(Y99:AB99) -> 11642.01
G100: (unit: kpcs) | N100: (unit: k$)
B102: 2021 Microdisplay - Display Quantity/Quarter
...

Sheet 2021-2025
B2: 2020-2025 Long Term Plan (submitted to JMGO in Q4 2020)
B4: - | D4: 2021 (Typical) | G4: 2022 | K4: 2023 | O4: 2024 | S4: 2025
D5: Q'ty | E5: ASP | F5: AMT | G5: Q'ty | H5: ASP | I5: ASP Variation | J5: AMT | K5: Q'ty | L5: ASP | M5: ASP Variation | N5: AMT | O5: Q'ty | P5: ASP | Q5: ASP Variation | R5: AMT | S5: Q'ty | T5: ASP | U5: ASP Variation | V5: AMT
B6: MD | C6: Controller | D6: ='2025 FCST'!#REF!+'2025 FCST'!EU292+'2025 FCST'!#REF! -> #REF! | E6: =F6/D6 -> #REF! | F6: ='2025 FCST'!#REF!+'2025 FCST'!EW292+'2025 FCST'!#REF! -> #REF! | G6: ='2025 FCST'!#REF!+'2025 FCST'!KZ292+'2025 FCST'!#REF! -> #REF! | H6: =J6/G6 -> #REF! | I6: -0.01 | J6: ='2025 FCST'!#REF!+'2025 FCST'!LB292+'2025 FCST'!#REF! -> #REF! | K6: =(K7+K8+K9+K10+K11)*0.75 -> 607.5 | L6: =H6+H6*M6 -> #REF! | M6: -0.015 | N6: =K6*L6 -> #REF! | O6: =(O7+O8+O9+O10+O11)*0.75 -> 1230 | P6: =L6+L6*Q6 -> #REF! | Q6: -0.02 | R6: =O6*P6 -> #REF! | S6: =(S7+S8+S9+S10+S11)*0.75 -> 2850 | T6: =P6+P6*U6 -> #REF! | U6: -0.025 | V6: =S6*T6 -> #REF!
C7: RDP370F | D7: ='2025 FCST'!EU201 -> 3.5 | E7: =F7/D7 -> 33 | F7: ='2025 FCST'!EW201 -> 115.5 | G7: ='2025 FCST'!KZ201 -> 8 | H7: =J7/G7 -> 34.78125 | I7: -0.03 | J7: ='2025 FCST'!LB201 -> 278.25 | K7: 450 | L7: =H7+H7*M7 -> 33.042187 | M7: -0.05 | N7: =K7*L7 -> 14868.984 | O7: 800 | P7: =L7+L7*Q7 -> 30.729234 | Q7: -0.07 | R7: =O7*P7 -> 24583.387 | S7: 1500 | T7: =P7+P7*U7 -> 28.270896 | U7: -0.08 | V7: =S7*T7 -> 42406.343
C8: RDP502(1)H | D8: ='2025 FCST'!#REF!+'2025 FCST'!EU322+'2025 FCST'!EU366 -> #REF! | E8: =F8/D8 -> #REF! | F8: ='2025 FCST'!#REF!+'2025 FCST'!EW322+'2025 FCST'!EW366 -> #REF! | G8: ='2025 FCST'!#REF!+'2025 FCST'!KZ322+'2025 FCST'!KZ366 -> #REF! | H8: =J8/G8 -> #REF! | I8: -0.03 | J8: ='2025 FCST'!#REF!+'2025 FCST'!LB322+'2025 FCST'!LB366 -> #REF! | K8: 50 | L8: =H8+H8*M8 -> #REF! | M8: -0.05 | N8: =K8*L8 -> #REF! | O8: 100 | P8: =L8+L8*Q8 -> #REF! | Q8: -0.07 | R8: =O8*P8 -> #REF! | S8: 200 | T8: =P8+P8*U8 -> #REF! | U8: -0.08 | V8: =S8*T8 -> #REF!
C9: RDP551F | D9: ='2025 FCST'!EU307 -> 1.3 | E9: =F9/D9 -> 62.307692 | F9: ='2025 FCST'!EW307 -> 81 | G9: ='2025 FCST'!KZ307 -> 5.5 | H9: =J9/G9 -> 66.909091 | I9: -0.03 | J9: ='2025 FCST'!LB307 -> 368 | K9: 100 | L9: =H9+H9*M9 -> 63.563636 | M9: -0.05 | N9: =K9*L9 -> 6356.3636 | O9: 200 | P9: =L9+L9*Q9 -> 59.114182 | Q9: -0.07 | R9: =O9*P9 -> 11822.836 | S9: 400 | T9: =P9+P9*U9 -> 54.385047 | U9: -0.08 | V9: =S9*T9 -> 21754.019
C10: RDPxxxU | D10: 0 | E10: 90 | F10: =D10*E10 -> 0 | G10: 0 | H10: 0 | I10: 0 | J10: 0 | K10: 10 | L10: 100 | M10: -0.0333 | N10: =K10*L10 -> 1000 | O10: 40 | P10: =L10+L10*Q10 -> 94.825 | Q10: -0.05175 | R10: =O10*P10 -> 3793 | S10: 200 | T10: =P10+P10*U10 -> 88.18725 | U10: -0.07 | V10: =S10*T10 -> 17637.45
C11: RDP250H | D11: ='2025 FCST'!EU143 -> 33.006 | E11: =F11/D11 -> 26.600921 | F11: ='2025 FCST'!EW143 -> 877.99 | G11: ='2025 FCST'!KZ143 -> 79 | H11: =J11/G11 -> 27.139241 | I11: -0.015 | J11: ='2025 FCST'!LB143 -> 2144 | K11: 200 | L11: =H11+H11*M11 -> 26.325063 | M11: -0.03 | N11: =K11*L11 -> 5265.0127 | O11: 500 | P11: =L11+L11*Q11 -> 25.00881 | Q11: -0.05 | R11: =O11*P11 -> 12504.405 | S11: 1500 | T11: =P11+P11*U11 -> 23.258193 | U11: -0.07 | V11: =S11*T11 -> 34887.29
C12: RDP390E2K Die | D12: ='2025 FCST'!EU399*242*0.9 -> 0 | E12: =F12/D12 -> #DIV/0! | F12: ='2025 FCST'!EW399 -> 0 | G12: ='2025 FCST'!KW399*242*0.9 -> 0 | H12: =J12/G12 -> #DIV/0! | I12: =(H12-E12)/E12 -> #DIV/0! | J12: ='2025 FCST'!KY399 -> 0 | K12: =1000*242*0.9/1000 -> 217.8 | L12: =H12+H12*M12 -> #DIV/0! | M12: -0.03 | N12: =K12*L12 -> #DIV/0! | O12: 450 | P12: =L12+L12*Q12 -> #DIV/0! | Q12: -0.03 | R12: =O12*P12 -> #DIV/0! | S12: 1000 | T12: =P12+P12*U12 -> #DIV/0! | U12: -0.03 | V12: =S12*T12 -> #DIV/0!
C13: RDPC340X | D13: 0 | E13: 0 | F13: 0 | G13: 0 | H13: 0 | I13: 0 | J13: 0 | K13: 200 | L13: 38 | M13: 0 | N13: =K13*L13 -> 7600 | O13: 500 | P13: =L13+L13*Q13 -> 36.86 | Q13: -0.03 | R13: =O13*P13 -> 18430 | S13: 1000 | T13: =P13+P13*U13 -> 35.7542 | U13: -0.03 | V13: =S13*T13 -> 35754.2
C14: LCoS Wafers Die | D14: ='2025 FCST'!EU155*288*0.9+'2025 FCST'!EU208*261*0.9+'2025 FCST'!EU348*165*0.9 -> 33.4125 | E14: =F14/D14 -> 13.279461 | F14: ='2025 FCST'!EW155+'2025 FCST'!EW208+'2025 FCST'!EW348 -> 443.7 | G14: ='2025 FCST'!KZ155*288*0.9+'2025 FCST'!KZ208*261*0.9+'2025 FCST'!KZ348*165*0.9 -> 39.8925 | H14: =J14/G14 -> 15.383844 | I14: 0 | J14: ='2025 FCST'!LB155+'2025 FCST'!LB208+'2025 FCST'!LB348 -> 613.7 | K14: 800 | L14: =H14+H14*M14 -> 14.922329 | M14: -0.03 | N14: =K14*L14 -> 11937.863 | O14: 1200 | P14: =L14+L14*Q14 -> 14.176212 | Q14: -0.05 | R14: =O14*P14 -> 17011.455 | S14: 1500 | T14: =P14+P14*U14 -> 13.183877 | U14: -0.07 | V14: =S14*T14 -> 19775.816
C15: uLED Wafer Die | D15: 0 | E15: 0 | F15: =D15*E15 -> 0 | G15: 0 | H15: 0 | I15: 0 | J15: =G15*H15 -> 0 | K15: 20 | L15: 10 | M15: 0 | N15: =K15*L15 -> 200 | O15: 500 | P15: =L15+L15*Q15 -> 9.7 | Q15: -0.03 | R15: =O15*P15 -> 4850 | S15: 2000 | T15: =P15+P15*U15 -> 9.215 | U15: -0.05 | V15: =S15*T15 -> 18430
C16: uOLED Wafer Die | D16: =('2025 FCST'!EU379+'2025 FCST'!EU380)*40+('2025 FCST'!EU383+'2025 FCST'!EU384+'2025 FCST'!EU385+'2025 FCST'!EU386+'2025 FCST'!EU394)*82 -> 1 | E16: =F16/D16 -> 53.55 | F16: ='2025 FCST'!EW379+'2025 FCST'!EW380+'2025 FCST'!EW383+'2025 FCST'!EW384+'2025 FCST'!EW385+'2025 FCST'!EW386+'2025 FCST'!EW394 -> 53.55 | G16: =('2025 FCST'!KZ379+'2025 FCST'!KZ380)*40+('2025 FCST'!KZ383+'2025 FCST'!KZ384+'2025 FCST'!KZ385+'2025 FCST'!KZ386+'2025 FCST'!KZ394)*82 -> 6.15 | H16: =J16/G16 -> 51.219512 | I16: 0 | J16: ='2025 FCST'!LB379+'2025 FCST'!LB380+'2025 FCST'!LB383+'2025 FCST'!LB384+'2025 FCST'!LB385+'2025 FCST'!LB386+'2025 FCST'!LB394 -> 315 | K16: 20 | L16: 10 | M16: 0 | N16: =K16*L16 -> 200 | O16: 500 | P16: =L16+L16*Q16 -> 9.7 | Q16: -0.03 | R16: =O16*P16 -> 4850 | S16: 1500 | T16: =P16+P16*U16 -> 9.409 | U16: -0.03 | V16: =S16*T16 -> 14113.5
C17: OE VISION | D17: ='2025 FCST'!EU418+'2025 FCST'!EU419+'2025 FCST'!EU420+'2025 FCST'!EU426 -> 0.576 | E17: =F17/D17 -> 980 | F17: ='2025 FCST'!EW418+'2025 FCST'!EW419+'2025 FCST'!EW420+'2025 FCST'!EW426 -> 564.48 | G17: ='2025 FCST'!KZ418+'2025 FCST'!KZ419+'2025 FCST'!KZ420+'2025 FCST'!KZ426 -> 0.84 | H17: 950 | I17: 0 | J17: ='2025 FCST'!LB418+'2025 FCST'!LB419+'2025 FCST'!LB420+'2025 FCST'!LB426 -> 823.2 | K17: 8 | L17: =H17+H17*M17 -> 931 | M17: -0.02 | N17: =K17*L17 -> 7448 | O17: 20 | P17: =L17+L17*Q17 -> 912.38 | Q17: -0.02 | R17: =O17*P17 -> 18247.6 | S17: 50 | T17: =P17+P17*U17 -> 894.1324 | U17: -0.02 | V17: =S17*T17 -> 44706.62
C18: F2 | D18: ='2025 FCST'!EU425 -> 0.6 | E18: =F18/D18 -> 700 | F18: ='2025 FCST'!EW425 -> 420 | G18: ='2025 FCST'!KZ425 -> 1.7 | H18: 300 | I18: =(H18-E18)/E18 -> -0.57142857 | J18: ='2025 FCST'!LB425 -> 1190 | K18: 8 | L18: =H18+H18*M18 -> 294 | M18: -0.02 | N18: =K18*L18 -> 2352 | O18: 15 | P18: =L18+L18*Q18 -> 288.12 | Q18: -0.02 | R18: =O18*P18 -> 4321.8 | S18: 50 | T18: =P18+P18*U18 -> 282.3576 | U18: -0.02 | V18: =S18*T18 -> 14117.88
C19: Contract | D19: 0 | E19: 0 | F19: ='2025 FCST'!EW456 -> 6990 | G19: 0 | H19: 0 | I19: 0 | J19: ='2025 FCST'!LB456 -> 3310 | K19: 0 | L19: 0 | M19: 0 | N19: 6500 | O19: 0 | P19: 0 | Q19: 0 | R19: 6500 | S19: 0 | T19: 0 | U19: 0 | V19: 6500
C20: Others | D20: 0 | E20: 0 | F20: =F25-SUM(F6:F19)-F21 -> #REF! | G20: 0 | H20: 0 | I20: 0 | J20: =J25-SUM(J6:J19)-J21 -> #REF! | K20: 0 | L20: 0 | M20: 0 | N20: =N25-SUM(N6:N19)-N21 -> #REF! | O20: 0 | P20: 0 | Q20: 0 | R20: =R25-SUM(R6:R19)-R21 -> #REF! | S20: 0 | T20: 0 | U20: 0 | V20: =V25-SUM(V6:V19)-V21 -> #REF!
B21: MTV | D21: ='2025 FCST'!EU99 -> 1496.503 | F21: ='2025 FCST'!EW99 -> 1029.7297 | G21: ='2025 FCST'!KZ99 -> 2804.006 | H21: =F21/D21+F21/D21*I21 -> 0.67432882 | I21: -0.02 | J21: ='2025 FCST'!LB99 -> 2027.8754 | K21: 4500 | L21: =H21+H21*M21 -> 0.66084225 | M21: -0.02 | N21: =K21*L21 -> 2973.7901 | O21: 4400 | P21: =L21+L21*Q21 -> 0.6476254 | Q21: -0.02 | R21: =O21*P21 -> 2849.5518 | S21: 4300 | T21: =P21+P21*U21 -> 0.63467289 | U21: -0.02 | V21: =S21*T21 -> 2729.0934
B22: Total | D22: =SUM(D6:D21) -> #REF! | F22: =SUM(F6:F21) -> #REF! | G22: =SUM(G6:G21) -> #REF! | H22: - | I22: - | J22: =SUM(J6:J21) -> #REF! | K22: =SUM(K6:K21) -> 7191.3 | L22: - | M22: - | N22: =SUM(N6:N21) -> #REF! | O22: =SUM(O6:O21) -> 10455 | P22: - | Q22: - | R22: =SUM(R6:R21) -> #REF! | S22: =SUM(S6:S21) -> 18050 | T22: - | U22: - | V22: =SUM(V6:V21) -> #REF!
V23: (unit: kpcs, k$)
F25: 6928 | J25: 25832 | N25: 62000 | R25: 125000 | V25: 270000
D42: 2021 | E42: 2022 | F42: 2023 | G42: 2024 | H42: 2025 | J42: CAGR
D43: =F22 -> #REF! | E43: =J22 -> #REF! | F43: =N22 -> #REF! | G43: =R22 -> #REF! | H43: =V22 -> #REF! | J43: =(H43/D43)^(1/4)-1 -> #REF!

Sheet 2025 FCST
B3: CY2026 | G3: 2026 | J3: 2026 | FI3: 2027 | FL3: 2027
B4: Model | C4: Customer | D4: Standard | E4: Application | F4: Location | G4: Jan '26 | P4: Feb. '26 | Y4: Mar '26 | AH4: CY25 1Q | AQ4: Apr. '26 | AZ4: May. '26 | BI4: Jun. '26 | BR4: CY26 2Q | CA4: Jul. '26 | CJ4: Aug. '26 | CS4: Sep '26 | DB4: CY26 3Q | DK4: Oct. '26 | DT4: Nov. '26 | EC4: Dec. '26 | EL4: CY26 4Q | EU4: CY26 Total | FE4: Model | FF4: Customer | FG4: Application | FH4: Location | FI4: Jan '27 | FR4: Feb. '27 | GA4: Mar '27 | GJ4: CY25 1Q | GS4: Apr. '27 | HB4: May. '27 | HK4: Jun. '27 | HT4: CY26 2Q | IC4: Jul. '27 | IL4: Aug. '27 | IU4: Sep '27 | JD4: CY26 3Q | JM4: Oct. '27 | JV4: Nov. '27 | KE4: Dec. '27 | KN4: CY26 4Q | KW4: CY27 Total
G5: FCST | J5: PLAN | M5: FCST vs. PLAN | P5: CLOSED | S5: PLAN | V5: FCST vs. PLAN | Y5: FCST | AB5: PLAN | AE5: FCST vs. PLAN | AH5: FCST | AK5: PLAN | AN5: FCST vs. PLAN | AQ5: FCST | AT5: PLAN | AW5: FCST vs. PLAN | AZ5: FCST | BC5: PLAN | BF5: FCST vs. PLAN | BI5: FCST | BL5: PLAN | BO5: FCST vs. PLAN | BR5: FCST | BU5: PLAN | BX5: FCST vs. PLAN | CA5: FCST | CD5: PLAN | CG5: FCST vs. PLAN | CJ5: FCST | CM5: PLAN | CP5: FCST vs. PLAN | CS5: FCST | CV5: PLAN | CY5: FCST vs. PLAN | DB5: FCST | DE5: PLAN | DH5: FCST vs. PLAN | DK5: FCST | DN5: PLAN | DQ5: FCST vs. PLAN | DT5: FCST | DW5: PLAN | DZ5: FCST vs. PLAN | EC5: FCST | EF5: PLAN | EI5: FCST vs. PLAN | EL5: FCST | EO5: PLAN | ER5: FCST vs. PLAN | EU5: FCST | EX5: PLAN | FA5: FCST vs. PLAN | FI5: FCST | FL5: PLAN | FO5: FCST vs. PLAN | FR5: FCST | FU5: PLAN | FX5: FCST vs. PLAN | GA5: FCST | GD5: PLAN | GG5: FCST vs. PLAN | GJ5: FCST | GM5: PLAN | GP5: FCST vs. PLAN | GS5: FCST | GV5: PLAN | GY5: FCST vs. PLAN | HB5: FCST | HE5: PLAN | HH5: FCST vs. PLAN | HK5: FCST | HN5: PLAN | HQ5: FCST vs. PLAN | HT5: FCST | HW5: PLAN | HZ5: FCST vs. PLAN | IC5: FCST | IF5: PLAN | II5: FCST vs. PLAN | IL5: FCST | IO5: PLAN | IR5: FCST vs. PLAN | IU5: FCST | IX5: PLAN | JA5: FCST vs. PLAN | JD5: FCST | JG5: PLAN | JJ5: FCST vs. PLAN | JM5: FCST | JP5: PLAN | JS5: FCST vs. PLAN | JV5: FCST | JY5: PLAN | KB5: FCST vs. PLAN | KE5: FCST | KH5: PLAN | KK5: FCST vs. PLAN | KN5: FCST | KQ5: PLAN | KT5: FCST vs. PLAN | KW5: FCST | KZ5: PLAN | LC5: FCST vs. PLAN
G6: Q'ty | H6: ASP | I6: AMT | J6: Q'ty | K6: ASP | L6: AMT | M6: Q'ty | N6: ASP | O6: AMT | P6: Q'ty | Q6: ASP | R6: AMT | S6: Q'ty | T6: ASP | U6: AMT | V6: Q'ty | W6: ASP | X6: AMT | Y6: Q'ty | Z6: ASP | AA6: AMT | AB6: Q'ty | AC6: ASP | AD6: AMT | AE6: Q'ty | AF6: ASP | AG6: AMT | AH6: Q'ty | AI6: ASP | AJ6: AMT | AK6: Q'ty | AL6: ASP | AM6: AMT | AN6: Q'ty | AO6: ASP | AP6: AMT | AQ6: Q'ty | AR6: ASP | AS6: AMT | AT6: Q'ty | AU6: ASP | AV6: AMT | AW6: Q'ty | AX6: ASP | AY6: AMT | AZ6: Q'ty | BA6: ASP | BB6: AMT | BC6: Q'ty | BD6: ASP | BE6: AMT | BF6: Q'ty | BG6: ASP | BH6: AMT | BI6: Q'ty | BJ6: ASP | BK6: AMT | BL6: Q'ty | BM6: ASP | BN6: AMT | BO6: Q'ty | BP6: ASP | BQ6: AMT | BR6: Q'ty | BS6: ASP | BT6: AMT | BU6: Q'ty | BV6: ASP | BW6: AMT | BX6: Q'ty | BY6: ASP | BZ6: AMT | CA6: Q'ty | CB6: ASP | CC6: AMT | CD6: Q'ty | CE6: ASP | CF6: AMT | CG6: Q'ty | CH6: ASP | CI6: AMT | CJ6: Q'ty | CK6: ASP | CL6: AMT | CM6: Q'ty | CN6: ASP | CO6: AMT | CP6: Q'ty | CQ6: ASP | CR6: AMT | CS6: Q'ty | CT6: ASP | CU6: AMT | CV6: Q'ty | CW6: ASP | CX6: AMT | CY6: Q'ty | CZ6: ASP | DA6: AMT | DB6: Q'ty | DC6: ASP | DD6: AMT | DE6: Q'ty | DF6: ASP | DG6: AMT | DH6: Q'ty | DI6: ASP | DJ6: AMT | DK6: Q'ty | DL6: ASP | DM6: AMT | DN6: Q'ty | DO6: ASP | DP6: AMT | DQ6: Q'ty | DR6: ASP | DS6: AMT | DT6: Q'ty | DU6: ASP | DV6: AMT | DW6: Q'ty | DX6: ASP | DY6: AMT | DZ6: Q'ty | EA6: ASP | EB6: AMT | EC6: Q'ty | ED6: ASP | EE6: AMT | EF6: Q'ty | EG6: ASP | EH6: AMT | EI6: Q'ty | EJ6: ASP | EK6: AMT | EL6: Q'ty | EM6: ASP | EN6: AMT | EO6: Q'ty | EP6: ASP | EQ6: AMT | ER6: Q'ty | ES6: ASP | ET6: AMT | EU6: Q'ty | EV6: ASP | EW6: AMT | EX6: Q'ty | EY6: ASP | EZ6: AMT | FA6: Q'ty | FB6: ASP | FC6: AMT | FI6: Q'ty | FJ6: ASP | FK6: AMT | FL6: Q'ty | FM6: ASP | FN6: AMT | FO6: Q'ty | FP6: ASP | FQ6: AMT | FR6: Q'ty | FS6: ASP | FT6: AMT | FU6: Q'ty | FV6: ASP | FW6: AMT | FX6: Q'ty | FY6: ASP | FZ6: AMT | GA6: Q'ty | GB6: ASP | GC6: AMT | GD6: Q'ty | GE6: ASP | GF6: AMT | GG6: Q'ty | GH6: ASP | GI6: AMT | GJ6: Q'ty | GK6: ASP | GL6: AMT | GM6: Q'ty | GN6: ASP | GO6: AMT | GP6: Q'ty | GQ6: ASP | GR6: AMT | GS6: Q'ty | GT6: ASP | GU6: AMT | GV6: Q'ty | GW6: ASP | GX6: AMT | GY6: Q'ty | GZ6: ASP | HA6: AMT | HB6: Q'ty | HC6: ASP | HD6: AMT | HE6: Q'ty | HF6: ASP | HG6: AMT | HH6: Q'ty | HI6: ASP | HJ6: AMT | HK6: Q'ty | HL6: ASP | HM6: AMT | HN6: Q'ty | HO6: ASP | HP6: AMT | HQ6: Q'ty | HR6: ASP | HS6: AMT | HT6: Q'ty | HU6: ASP | HV6: AMT | HW6: Q'ty | HX6: ASP | HY6: AMT | HZ6: Q'ty | IA6: ASP | IB6: AMT | IC6: Q'ty | ID6: ASP | IE6: AMT | IF6: Q'ty | IG6: ASP | IH6: AMT | II6: Q'ty | IJ6: ASP | IK6: AMT | IL6: Q'ty | IM6: ASP | IN6: AMT | IO6: Q'ty | IP6: ASP | IQ6: AMT | IR6: Q'ty | IS6: ASP | IT6: AMT | IU6: Q'ty | IV6: ASP | IW6: AMT | IX6: Q'ty | IY6: ASP | IZ6: AMT | JA6: Q'ty | JB6: ASP | JC6: AMT | JD6: Q'ty | JE6: ASP | JF6: AMT | JG6: Q'ty | JH6: ASP | JI6: AMT | JJ6: Q'ty | JK6: ASP | JL6: AMT | JM6: Q'ty | JN6: ASP | JO6: AMT | JP6: Q'ty | JQ6: ASP | JR6: AMT | JS6: Q'ty | JT6: ASP | JU6: AMT | JV6: Q'ty | JW6: ASP | JX6: AMT | JY6: Q'ty | JZ6: ASP | KA6: AMT | KB6: Q'ty | KC6: ASP | KD6: AMT | KE6: Q'ty | KF6: ASP | KG6: AMT | KH6: Q'ty | KI6: ASP | KJ6: AMT | KK6: Q'ty | KL6: ASP | KM6: AMT | KN6: Q'ty | KO6: ASP | KP6: AMT | KQ6: Q'ty | KR6: ASP | KS6: AMT | KT6: Q'ty | KU6: ASP | KV6: AMT | KW6: Q'ty | KX6: ASP | KY6: AMT | KZ6: Q'ty | LA6: ASP | LB6: AMT | LC6: Q'ty | LD6: ASP | LE6: AMT
E8: MTV | I8: =G8*H8 -> 0 | L8: =J8*K8 -> 0 | M8: =G8-J8 -> 0 | N8: =H8-K8 -> 0 | O8: =I8-L8 -> 0 | R8: =P8*Q8 -> 0 | U8: =S8*T8 -> 0 | V8: =P8-S8 -> 0 | W8: =Q8-T8 -> 0 | X8: =R8-U8 -> 0 | AA8: =Y8*Z8 -> 0 | AD8: =AB8*AC8 -> 0 | AE8: =Y8-AB8 -> 0 | AF8: =Z8-AC8 -> 0 | AG8: =AA8-AD8 -> 0 | AH8: =G8+P8+Y8 -> 0 | AI8: =IF(AJ8,AJ8/AH8,0) -> 0 | AJ8: =I8+R8+AA8 -> 0 | AK8: =J8+S8+AB8 -> 0 | AL8: =IF(AM8,AM8/AK8,0) -> 0 | AM8: =L8+U8+AD8 -> 0 | AN8: =AH8-AK8 -> 0 | AO8: =AI8-AL8 -> 0 | AP8: =AJ8-AM8 -> 0 | AS8: =AQ8*AR8 -> 0 | AV8: =AT8*AU8 -> 0 | AW8: =AQ8-AT8 -> 0 | AX8: =AR8-AU8 -> 0 | AY8: =AS8-AV8 -> 0 | BB8: =AZ8*BA8 -> 0 | BE8: =BC8*BD8 -> 0 | BF8: =AZ8-BC8 -> 0 | BG8: =BA8-BD8 -> 0 | BH8: =BB8-BE8 -> 0 | BK8: =BI8*BJ8 -> 0 | BN8: =BL8*BM8 -> 0 | BO8: =BI8-BL8 -> 0 | BP8: =BJ8-BM8 -> 0 | BQ8: =BK8-BN8 -> 0 | BR8: =AQ8+AZ8+BI8 -> 0 | BS8: =IF(BT8,BT8/BR8,0) -> 0 | BT8: =AS8+BB8+BK8 -> 0 | BU8: =AT8+BC8+BL8 -> 0 | BV8: =IF(BW8,BW8/BU8,0) -> 0 | BW8: =AV8+BE8+BN8 -> 0 | BX8: =BR8-BU8 -> 0 | BY8: =BS8-BV8 -> 0 | BZ8: =BT8-BW8 -> 0 | CC8: =CA8*CB8 -> 0 | CF8: =CD8*CE8 -> 0 | CG8: =CA8-CD8 -> 0 | CH8: =CB8-CE8 -> 0 | CI8: =CC8-CF8 -> 0 | CL8: =CJ8*CK8 -> 0 | CO8: =CM8*CN8 -> 0 | CP8: =CJ8-CM8 -> 0 | CQ8: =CK8-CN8 -> 0 | CR8: =CL8-CO8 -> 0 | CU8: =CS8*CT8 -> 0 | CX8: =CV8*CW8 -> 0 | CY8: =CS8-CV8 -> 0 | CZ8: =CT8-CW8 -> 0 | DA8: =CU8-CX8 -> 0 | DB8: =CA8+CJ8+CS8 -> 0 | DC8: =IF(DD8,DD8/DB8,0) -> 0 | DD8: =CC8+CL8+CU8 -> 0 | DE8: =CD8+CM8+CV8 -> 0 | DF8: =IF(DG8,DG8/DE8,0) -> 0 | DG8: =CF8+CO8+CX8 -> 0 | DH8: =DB8-DE8 -> 0 | DI8: =DC8-DF8 -> 0 | DJ8: =DD8-DG8 -> 0 | DM8: =DK8*DL8 -> 0 | DP8: =DN8*DO8 -> 0 | DQ8: =DK8-DN8 -> 0 | DR8: =DL8-DO8 -> 0 | DS8: =DM8-DP8 -> 0 | DV8: =DT8*DU8 -> 0 | DY8: =DW8*DX8 -> 0 | DZ8: =DT8-DW8 -> 0 | EA8: =DU8-DX8 -> 0 | EB8: =DV8-DY8 -> 0 | EE8: =EC8*ED8 -> 0 | EH8: =EF8*EG8 -> 0 | EI8: =EC8-EF8 -> 0 | EJ8: =ED8-EG8 -> 0 | EK8: =EE8-EH8 -> 0 | EL8: =DK8+DT8+EC8 -> 0 | EM8: =IF(EN8,EN8/EL8,0) -> 0 | EN8: =DM8+DV8+EE8 -> 0 | EO8: =DN8+DW8+EF8 -> 0 | EP8: =IF(EQ8,EQ8/EO8,0) -> 0 | EQ8: =DP8+DY8+EH8 -> 0 | ER8: =EL8-EO8 -> 0 | ES8: =EM8-EP8 -> 0 | ET8: =EN8-EQ8 -> 0 | EU8: =AH8+BR8+DB8+EL8 -> 0 | EV8: =IF(EW8,EW8/EU8,0) -> 0 | EW8: =AJ8+BT8+DD8+EN8 -> 0 | EX8: =AK8+BU8+DE8+EO8 -> 0 | EY8: =IF(EZ8,EZ8/EX8,0) -> 0 | EZ8: =AM8+BW8+DG8+EQ8 -> 0 | FA8: =EU8-EX8 -> 0 | FB8: =EV8-EY8 -> 0 | FC8: =EW8-EZ8 -> 0 | FE8: MTV319AW7 | FF8: SAMSUNG | FH8: K | FK8: =FI8*FJ8 -> 0 | FN8: =FL8*FM8 -> 0 | FO8: =FI8-FL8 -> 0 | FP8: =FJ8-FM8 -> 0 | FQ8: =FK8-FN8 -> 0 | FT8: =FR8*FS8 -> 0 | FW8: =FU8*FV8 -> 0 | FX8: =FR8-FU8 -> 0 | FY8: =FS8-FV8 -> 0 | FZ8: =FT8-FW8 -> 0 | GC8: =GA8*GB8 -> 0 | GF8: =GD8*GE8 -> 0 | GG8: =GA8-GD8 -> 0 | GH8: =GB8-GE8 -> 0 | GI8: =GC8-GF8 -> 0 | GJ8: =FI8+FR8+GA8 -> 0 | GK8: =IF(GL8,GL8/GJ8,0) -> 0 | GL8: =FK8+FT8+GC8 -> 0 | GM8: =FL8+FU8+GD8 -> 0 | GN8: =IF(GO8,GO8/GM8,0) -> 0 | GO8: =FN8+FW8+GF8 -> 0 | GP8: =GJ8-GM8 -> 0 | GQ8: =GK8-GN8 -> 0 | GR8: =GL8-GO8 -> 0 | GU8: =GS8*GT8 -> 0 | GX8: =GV8*GW8 -> 0 | GY8: =GS8-GV8 -> 0 | GZ8: =GT8-GW8 -> 0 | HA8: =GU8-GX8 -> 0 | HD8: =HB8*HC8 -> 0 | HG8: =HE8*HF8 -> 0 | HH8: =HB8-HE8 -> 0 | HI8: =HC8-HF8 -> 0 | HJ8: =HD8-HG8 -> 0 | HM8: =HK8*HL8 -> 0 | HP8: =HN8*HO8 -> 0 | HQ8: =HK8-HN8 -> 0 | HR8: =HL8-HO8 -> 0 | HS8: =HM8-HP8 -> 0 | HT8: =GS8+HB8+HK8 -> 0 | HU8: =IF(HV8,HV8/HT8,0) -> 0 | HV8: =GU8+HD8+HM8 -> 0 | HW8: =GV8+HE8+HN8 -> 0 | HX8: =IF(HY8,HY8/HW8,0) -> 0 | HY8: =GX8+HG8+HP8 -> 0 | HZ8: =HT8-HW8 -> 0 | IA8: =HU8-HX8 -> 0 | IB8: =HV8-HY8 -> 0 | IE8: =IC8*ID8 -> 0 | IH8: =IF8*IG8 -> 0 | II8: =IC8-IF8 -> 0 | IJ8: =ID8-IG8 -> 0 | IK8: =IE8-IH8 -> 0 | IN8: =IL8*IM8 -> 0 | IQ8: =IO8*IP8 -> 0 | IR8: =IL8-IO8 -> 0 | IS8: =IM8-IP8 -> 0 | IT8: =IN8-IQ8 -> 0 | IW8: =IU8*IV8 -> 0 | IZ8: =IX8*IY8 -> 0 | JA8: =IU8-IX8 -> 0 | JB8: =IV8-IY8 -> 0 | JC8: =IW8-IZ8 -> 0 | JD8: =IC8+IL8+IU8 -> 0 | JE8: =IF(JF8,JF8/JD8,0) -> 0 | JF8: =IE8+IN8+IW8 -> 0 | JG8: =IF8+IO8+IX8 -> 0 | JH8: =IF(JI8,JI8/JG8,0) -> 0 | JI8: =IH8+IQ8+IZ8 -> 0 | JJ8: =JD8-JG8 -> 0 | JK8: =JE8-JH8 -> 0 | JL8: =JF8-JI8 -> 0 | JO8: =JM8*JN8 -> 0 | JR8: =JP8*JQ8 -> 0 | JS8: =JM8-JP8 -> 0 | JT8: =JN8-JQ8 -> 0 | JU8: =JO8-JR8 -> 0 | JX8: =JV8*JW8 -> 0 | KA8: =JY8*JZ8 -> 0 | KB8: =JV8-JY8 -> 0 | KC8: =JW8-JZ8 -> 0 | KD8: =JX8-KA8 -> 0 | KG8: =KE8*KF8 -> 0 | KJ8: =KH8*KI8 -> 0 | KK8: =KE8-KH8 -> 0 | KL8: =KF8-KI8 -> 0 | KM8: =KG8-KJ8 -> 0 | KN8: =JM8+JV8+KE8 -> 0 | KO8: =IF(KP8,KP8/KN8,0) -> 0 | KP8: =JO8+JX8+KG8 -> 0 | KQ8: =JP8+JY8+KH8 -> 0 | KR8: =IF(KS8,KS8/KQ8,0) -> 0 | KS8: =JR8+KA8+KJ8 -> 0 | KT8: =KN8-KQ8 -> 0 | KU8: =KO8-KR8 -> 0 | KV8: =KP8-KS8 -> 0 | KW8: =GJ8+HT8+JD8+KN8 -> 0 | KX8: =IF(KY8,KY8/KW8,0) -> 0 | KY8: =GL8+HV8+JF8+KP8 -> 0 | KZ8: =GM8+HW8+JG8+KQ8 -> 0 | LA8: =IF(LB8,LB8/KZ8,0) -> 0 | LB8: =GO8+HY8+JI8+KS8 -> 0 | LC8: =KW8-KZ8 -> 0 | LD8: =KX8-LA8 -> 0 | LE8: =KY8-LB8 -> 0
E9: MTV | I9: =G9*H9 -> 0 | L9: =J9*K9 -> 0 | M9: =G9-J9 -> 0 | N9: =H9-K9 -> 0 | O9: =I9-L9 -> 0 | R9: =P9*Q9 -> 0 | U9: =S9*T9 -> 0 | V9: =P9-S9 -> 0 | W9: =Q9-T9 -> 0 | X9: =R9-U9 -> 0 | AA9: =Y9*Z9 -> 0 | AD9: =AB9*AC9 -> 0 | AE9: =Y9-AB9 -> 0 | AF9: =Z9-AC9 -> 0 | AG9: =AA9-AD9 -> 0 | AH9: =G9+P9+Y9 -> 0 | AI9: =IF(AJ9,AJ9/AH9,0) -> 0 | AJ9: =I9+R9+AA9 -> 0 | AK9: =J9+S9+AB9 -> 0 | AL9: =IF(AM9,AM9/AK9,0) -> 0 | AM9: =L9+U9+AD9 -> 0 | AN9: =AH9-AK9 -> 0 | AO9: =AI9-AL9 -> 0 | AP9: =AJ9-AM9 -> 0 | AS9: =AQ9*AR9 -> 0 | AV9: =AT9*AU9 -> 0 | AW9: =AQ9-AT9 -> 0 | AX9: =AR9-AU9 -> 0 | AY9: =AS9-AV9 -> 0 | BB9: =AZ9*BA9 -> 0 | BE9: =BC9*BD9 -> 0 | BF9: =AZ9-BC9 -> 0 | BG9: =BA9-BD9 -> 0 | BH9: =BB9-BE9 -> 0 | BK9: =BI9*BJ9 -> 0 | BN9: =BL9*BM9 -> 0 | BO9: =BI9-BL9 -> 0 | BP9: =BJ9-BM9 -> 0 | BQ9: =BK9-BN9 -> 0 | BR9: =AQ9+AZ9+BI9 -> 0 | BS9: =IF(BT9,BT9/BR9,0) -> 0 | BT9: =AS9+BB9+BK9 -> 0 | BU9: =AT9+BC9+BL9 -> 0 | BV9: =IF(BW9,BW9/BU9,0) -> 0 | BW9: =AV9+BE9+BN9 -> 0 | BX9: =BR9-BU9 -> 0 | BY9: =BS9-BV9 -> 0 | BZ9: =BT9-BW9 -> 0 | CC9: =CA9*CB9 -> 0 | CF9: =CD9*CE9 -> 0 | CG9: =CA9-CD9 -> 0 | CH9: =CB9-CE9 -> 0 | CI9: =CC9-CF9 -> 0 | CL9: =CJ9*CK9 -> 0 | CO9: =CM9*CN9 -> 0 | CP9: =CJ9-CM9 -> 0 | CQ9: =CK9-CN9 -> 0 | CR9: =CL9-CO9 -> 0 | CU9: =CS9*CT9 -> 0 | CX9: =CV9*CW9 -> 0 | CY9: =CS9-CV9 -> 0 | CZ9: =CT9-CW9 -> 0 | DA9: =CU9-CX9 -> 0 | DB9: =CA9+CJ9+CS9 -> 0 | DC9: =IF(DD9,DD9/DB9,0) -> 0 | DD9: =CC9+CL9+CU9 -> 0 | DE9: =CD9+CM9+CV9 -> 0 | DF9: =IF(DG9,DG9/DE9,0) -> 0 | DG9: =CF9+CO9+CX9 -> 0 | DH9: =DB9-DE9 -> 0 | DI9: =DC9-DF9 -> 0 | DJ9: =DD9-DG9 -> 0 | DM9: =DK9*DL9 -> 0 | DP9: =DN9*DO9 -> 0 | DQ9: =DK9-DN9 -> 0 | DR9: =DL9-DO9 -> 0 | DS9: =DM9-DP9 -> 0 | DV9: =DT9*DU9 -> 0 | DY9: =DW9*DX9 -> 0 | DZ9: =DT9-DW9 -> 0 | EA9: =DU9-DX9 -> 0 | EB9: =DV9-DY9 -> 0 | EE9: =EC9*ED9 -> 0 | EH9: =EF9*EG9 -> 0 | EI9: =EC9-EF9 -> 0 | EJ9: =ED9-EG9 -> 0 | EK9: =EE9-EH9 -> 0 | EL9: =DK9+DT9+EC9 -> 0 | EM9: =IF(EN9,EN9/EL9,0) -> 0 | EN9: =DM9+DV9+EE9 -> 0 | EO9: =DN9+DW9+EF9 -> 0 | EP9: =IF(EQ9,EQ9/EO9,0) -> 0 | EQ9: =DP9+DY9+EH9 -> 0 | ER9: =EL9-EO9 -> 0 | ES9: =EM9-EP9 -> 0 | ET9: =EN9-EQ9 -> 0 | EU9: =AH9+BR9+DB9+EL9 -> 0 | EV9: =IF(EW9,EW9/EU9,0) -> 0 | EW9: =AJ9+BT9+DD9+EN9 -> 0 | EX9: =AK9+BU9+DE9+EO9 -> 0 | EY9: =IF(EZ9,EZ9/EX9,0) -> 0 | EZ9: =AM9+BW9+DG9+EQ9 -> 0 | FA9: =EU9-EX9 -> 0 | FB9: =EV9-EY9 -> 0 | FC9: =EW9-EZ9 -> 0 | FK9: =FI9*FJ9 -> 0 | FN9: =FL9*FM9 -> 0 | FO9: =FI9-FL9 -> 0 | FP9: =FJ9-FM9 -> 0 | FQ9: =FK9-FN9 -> 0 | FT9: =FR9*FS9 -> 0 | FW9: =FU9*FV9 -> 0 | FX9: =FR9-FU9 -> 0 | FY9: =FS9-FV9 -> 0 | FZ9: =FT9-FW9 -> 0 | GC9: =GA9*GB9 -> 0 | GF9: =GD9*GE9 -> 0 | GG9: =GA9-GD9 -> 0 | GH9: =GB9-GE9 -> 0 | GI9: =GC9-GF9 -> 0 | GJ9: =FI9+FR9+GA9 -> 0 | GK9: =IF(GL9,GL9/GJ9,0) -> 0 | GL9: =FK9+FT9+GC9 -> 0 | GM9: =FL9+FU9+GD9 -> 0 | GN9: =IF(GO9,GO9/GM9,0) -> 0 | GO9: =FN9+FW9+GF9 -> 0 | GP9: =GJ9-GM9 -> 0 | GQ9: =GK9-GN9 -> 0 | GR9: =GL9-GO9 -> 0 | GU9: =GS9*GT9 -> 0 | GX9: =GV9*GW9 -> 0 | GY9: =GS9-GV9 -> 0 | GZ9: =GT9-GW9 -> 0 | HA9: =GU9-GX9 -> 0 | HD9: =HB9*HC9 -> 0 | HG9: =HE9*HF9 -> 0 | HH9: =HB9-HE9 -> 0 | HI9: =HC9-HF9 -> 0 | HJ9: =HD9-HG9 -> 0 | HM9: =HK9*HL9 -> 0 | HP9: =HN9*HO9 -> 0 | HQ9: =HK9-HN9 -> 0 | HR9: =HL9-HO9 -> 0 | HS9: =HM9-HP9 -> 0 | HT9: =GS9+HB9+HK9 -> 0 | HU9: =IF(HV9,HV9/HT9,0) -> 0 | HV9: =GU9+HD9+HM9 -> 0 | HW9: =GV9+HE9+HN9 -> 0 | HX9: =IF(HY9,HY9/HW9,0) -> 0 | HY9: =GX9+HG9+HP9 -> 0 | HZ9: =HT9-HW9 -> 0 | IA9: =HU9-HX9 -> 0 | IB9: =HV9-HY9 -> 0 | IE9: =IC9*ID9 -> 0 | IH9: =IF9*IG9 -> 0 | II9: =IC9-IF9 -> 0 | IJ9: =ID9-IG9 -> 0 | IK9: =IE9-IH9 -> 0 | IN9: =IL9*IM9 -> 0 | IQ9: =IO9*IP9 -> 0 | IR9: =IL9-IO9 -> 0 | IS9: =IM9-IP9 -> 0 | IT9: =IN9-IQ9 -> 0 | IW9: =IU9*IV9 -> 0 | IZ9: =IX9*IY9 -> 0 | JA9: =IU9-IX9 -> 0 | JB9: =IV9-IY9 -> 0 | JC9: =IW9-IZ9 -> 0 | JD9: =IC9+IL9+IU9 -> 0 | JE9: =IF(JF9,JF9/JD9,0) -> 0 | JF9: =IE9+IN9+IW9 -> 0 | JG9: =IF9+IO9+IX9 -> 0 | JH9: =IF(JI9,JI9/JG9,0) -> 0 | JI9: =IH9+IQ9+IZ9 -> 0 | JJ9: =JD9-JG9 -> 0 | JK9: =JE9-JH9 -> 0 | JL9: =JF9-JI9 -> 0 | JO9: =JM9*JN9 -> 0 | JR9: =JP9*JQ9 -> 0 | JS9: =JM9-JP9 -> 0 | JT9: =JN9-JQ9 -> 0 | JU9: =JO9-JR9 -> 0 | JX9: =JV9*JW9 -> 0 | KA9: =JY9*JZ9 -> 0 | KB9: =JV9-JY9 -> 0 | KC9: =JW9-JZ9 -> 0 | KD9: =JX9-KA9 -> 0 | KG9: =KE9*KF9 -> 0 | KJ9: =KH9*KI9 -> 0 | KK9: =KE9-KH9 -> 0 | KL9: =KF9-KI9 -> 0 | KM9: =KG9-KJ9 -> 0 | KN9: =JM9+JV9+KE9 -> 0 | KO9: =IF(KP9,KP9/KN9,0) -> 0 | KP9: =JO9+JX9+KG9 -> 0 | KQ9: =JP9+JY9+KH9 -> 0 | KR9: =IF(KS9,KS9/KQ9,0) -> 0 | KS9: =JR9+KA9+KJ9 -> 0 | KT9: =KN9-KQ9 -> 0 | KU9: =KO9-KR9 -> 0 | KV9: =KP9-KS9 -> 0 | KW9: =GJ9+HT9+JD9+KN9 -> 0 | KX9: =IF(KY9,KY9/KW9,0) -> 0 | KY9: =GL9+HV9+JF9+KP9 -> 0 | KZ9: =GM9+HW9+JG9+KQ9 -> 0 | LA9: =IF(LB9,LB9/KZ9,0) -> 0 | LB9: =GO9+HY9+JI9+KS9 -> 0 | LC9: =KW9-KZ9 -> 0 | LD9: =KX9-LA9 -> 0 | LE9: =KY9-LB9 -> 0
E10: MTV | I10: =G10*H10 -> 0 | L10: =J10*K10 -> 0 | M10: =G10-J10 -> 0 | N10: =H10-K10 -> 0 | O10: =I10-L10 -> 0 | R10: =P10*Q10 -> 0 | U10: =S10*T10 -> 0 | V10: =P10-S10 -> 0 | W10: =Q10-T10 -> 0 | X10: =R10-U10 -> 0 | AA10: =Y10*Z10 -> 0 | AD10: =AB10*AC10 -> 0 | AE10: =Y10-AB10 -> 0 | AF10: =Z10-AC10 -> 0 | AG10: =AA10-AD10 -> 0 | AH10: =G10+P10+Y10 -> 0 | AI10: =IF(AJ10,AJ10/AH10,0) -> 0 | AJ10: =I10+R10+AA10 -> 0 | AK10: =J10+S10+AB10 -> 0 | AL10: =IF(AM10,AM10/AK10,0) -> 0 | AM10: =L10+U10+AD10 -> 0 | AN10: =AH10-AK10 -> 0 | AO10: =AI10-AL10 -> 0 | AP10: =AJ10-AM10 -> 0 | AS10: =AQ10*AR10 -> 0 | AV10: =AT10*AU10 -> 0 | AW10: =AQ10-AT10 -> 0 | AX10: =AR10-AU10 -> 0 | AY10: =AS10-AV10 -> 0 | BB10: =AZ10*BA10 -> 0 | BE10: =BC10*BD10 -> 0 | BF10: =AZ10-BC10 -> 0 | BG10: =BA10-BD10 -> 0 | BH10: =BB10-BE10 -> 0 | BK10: =BI10*BJ10 -> 0 | BN10: =BL10*BM10 -> 0 | BO10: =BI10-BL10 -> 0 | BP10: =BJ10-BM10 -> 0 | BQ10: =BK10-BN10 -> 0 | BR10: =AQ10+AZ10+BI10 -> 0 | BS10: =IF(BT10,BT10/BR10,0) -> 0 | BT10: =AS10+BB10+BK10 -> 0 | BU10: =AT10+BC10+BL10 -> 0 | BV10: =IF(BW10,BW10/BU10,0) -> 0 | BW10: =AV10+BE10+BN10 -> 0 | BX10: =BR10-BU10 -> 0 | BY10: =BS10-BV10 -> 0 | BZ10: =BT10-BW10 -> 0 | CC10: =CA10*CB10 -> 0 | CF10: =CD10*CE10 -> 0 | CG10: =CA10-CD10 -> 0 | CH10: =CB10-CE10 -> 0 | CI10: =CC10-CF10 -> 0 | CL10: =CJ10*CK10 -> 0 | CO10: =CM10*CN10 -> 0 | CP10: =CJ10-CM10 -> 0 | CQ10: =CK10-CN10 -> 0 | CR10: =CL10-CO10 -> 0 | CU10: =CS10*CT10 -> 0 | CX10: =CV10*CW10 -> 0 | CY10: =CS10-CV10 -> 0 | CZ10: =CT10-CW10 -> 0 | DA10: =CU10-CX10 -> 0 | DB10: =CA10+CJ10+CS10 -> 0 | DC10: =IF(DD10,DD10/DB10,0) -> 0 | DD10: =CC10+CL10+CU10 -> 0 | DE10: =CD10+CM10+CV10 -> 0 | DF10: =IF(DG10,DG10/DE10,0) -> 0 | DG10: =CF10+CO10+CX10 -> 0 | DH10: =DB10-DE10 -> 0 | DI10: =DC10-DF10 -> 0 | DJ10: =DD10-DG10 -> 0 | DM10: =DK10*DL10 -> 0 | DP10: =DN10*DO10 -> 0 | DQ10: =DK10-DN10 -> 0 | DR10: =DL10-DO10 -> 0 | DS10: =DM10-DP10 -> 0 | DV10: =DT10*DU10 -> 0 | DY10: =DW10*DX10 -> 0 | DZ10: =DT10-DW10 -> 0 | EA10: =DU10-DX10 -> 0 | EB10: =DV10-DY10 -> 0 | EE10: =EC10*ED10 -> 0 | EH10: =EF10*EG10 -> 0 | EI10: =EC10-EF10 -> 0 | EJ10: =ED10-EG10 -> 0 | EK10: =EE10-EH10 -> 0 | EL10: =DK10+DT10+EC10 -> 0 | EM10: =IF(EN10,EN10/EL10,0) -> 0 | EN10: =DM10+DV10+EE10 -> 0 | EO10: =DN10+DW10+EF10 -> 0 | EP10: =IF(EQ10,EQ10/EO10,0) -> 0 | EQ10: =DP10+DY10+EH10 -> 0 | ER10: =EL10-EO10 -> 0 | ES10: =EM10-EP10 -> 0 | ET10: =EN10-EQ10 -> 0 | EU10: =AH10+BR10+DB10+EL10 -> 0 | EV10: =IF(EW10,EW10/EU10,0) -> 0 | EW10: =AJ10+BT10+DD10+EN10 -> 0 | EX10: =AK10+BU10+DE10+EO10 -> 0 | EY10: =IF(EZ10,EZ10/EX10,0) -> 0 | EZ10: =AM10+BW10+DG10+EQ10 -> 0 | FA10: =EU10-EX10 -> 0 | FB10: =EV10-EY10 -> 0 | FC10: =EW10-EZ10 -> 0 | FK10: =FI10*FJ10 -> 0 | FN10: =FL10*FM10 -> 0 | FO10: =FI10-FL10 -> 0 | FP10: =FJ10-FM10 -> 0 | FQ10: =FK10-FN10 -> 0 | FT10: =FR10*FS10 -> 0 | FW10: =FU10*FV10 -> 0 | FX10: =FR10-FU10 -> 0 | FY10: =FS10-FV10 -> 0 | FZ10: =FT10-FW10 -> 0 | GC10: =GA10*GB10 -> 0 | GF10: =GD10*GE10 -> 0 | GG10: =GA10-GD10 -> 0 | GH10: =GB10-GE10 -> 0 | GI10: =GC10-GF10 -> 0 | GJ10: =FI10+FR10+GA10 -> 0 | GK10: =IF(GL10,GL10/GJ10,0) -> 0 | GL10: =FK10+FT10+GC10 -> 0 | GM10: =FL10+FU10+GD10 -> 0 | GN10: =IF(GO10,GO10/GM10,0) -> 0 | GO10: =FN10+FW10+GF10 -> 0 | GP10: =GJ10-GM10 -> 0 | GQ10: =GK10-GN10 -> 0 | GR10: =GL10-GO10 -> 0 | GU10: =GS10*GT10 -> 0 | GX10: =GV10*GW10 -> 0 | GY10: =GS10-GV10 -> 0 | GZ10: =GT10-GW10 -> 0 | HA10: =GU10-GX10 -> 0 | HD10: =HB10*HC10 -> 0 | HG10: =HE10*HF10 -> 0 | HH10: =HB10-HE10 -> 0 | HI10: =HC10-HF10 -> 0 | HJ10: =HD10-HG10 -> 0 | HM10: =HK10*HL10 -> 0 | HP10: =HN10*HO10 -> 0 | HQ10: =HK10-HN10 -> 0 | HR10: =HL10-HO10 -> 0 | HS10: =HM10-HP10 -> 0 | HT10: =GS10+HB10+HK10 -> 0 | HU10: =IF(HV10,HV10/HT10,0) -> 0 | HV10: =GU10+HD10+HM10 -> 0 | HW10: =GV10+HE10+HN10 -> 0 | HX10: =IF(HY10,HY10/HW10,0) -> 0 | HY10: =GX10+HG10+HP10 -> 0 | HZ10: =HT10-HW10 -> 0 | IA10: =HU10-HX10 -> 0 | IB10: =HV10-HY10 -> 0 | IE10: =IC10*ID10 -> 0 | IH10: =IF10*IG10 -> 0 | II10: =IC10-IF10 -> 0 | IJ10: =ID10-IG10 -> 0 | IK10: =IE10-IH10 -> 0 | IN10: =IL10*IM10 -> 0 | IQ10: =IO10*IP10 -> 0 | IR10: =IL10-IO10 -> 0 | IS10: =IM10-IP10 -> 0 | IT10: =IN10-IQ10 -> 0 | IW10: =IU10*IV10 -> 0 | IZ10: =IX10*IY10 -> 0 | JA10: =IU10-IX10 -> 0 | JB10: =IV10-IY10 -> 0 | JC10: =IW10-IZ10 -> 0 | JD10: =IC10+IL10+IU10 -> 0 | JE10: =IF(JF10,JF10/JD10,0) -> 0 | JF10: =IE10+IN10+IW10 -> 0 | JG10: =IF10+IO10+IX10 -> 0 | JH10: =IF(JI10,JI10/JG10,0) -> 0 | JI10: =IH10+IQ10+IZ10 -> 0 | JJ10: =JD10-JG10 -> 0 | JK10: =JE10-JH10 -> 0 | JL10: =JF10-JI10 -> 0 | JO10: =JM10*JN10 -> 0 | JR10: =JP10*JQ10 -> 0 | JS10: =JM10-JP10 -> 0 | JT10: =JN10-JQ10 -> 0 | JU10: =JO10-JR10 -> 0 | JX10: =JV10*JW10 -> 0 | KA10: =JY10*JZ10 -> 0 | KB10: =JV10-JY10 -> 0 | KC10: =JW10-JZ10 -> 0 | KD10: =JX10-KA10 -> 0 | KG10: =KE10*KF10 -> 0 | KJ10: =KH10*KI10 -> 0 | KK10: =KE10-KH10 -> 0 | KL10: =KF10-KI10 -> 0 | KM10: =KG10-KJ10 -> 0 | KN10: =JM10+JV10+KE10 -> 0 | KO10: =IF(KP10,KP10/KN10,0) -> 0 | KP10: =JO10+JX10+KG10 -> 0 | KQ10: =JP10+JY10+KH10 -> 0 | KR10: =IF(KS10,KS10/KQ10,0) -> 0 | KS10: =JR10+KA10+KJ10 -> 0 | KT10: =KN10-KQ10 -> 0 | KU10: =KO10-KR10 -> 0 | KV10: =KP10-KS10 -> 0 | KW10: =GJ10+HT10+JD10+KN10 -> 0 | KX10: =IF(KY10,KY10/KW10,0) -> 0 | KY10: =GL10+HV10+JF10+KP10 -> 0 | KZ10: =GM10+HW10+JG10+KQ10 -> 0 | LA10: =IF(LB10,LB10/KZ10,0) -> 0 | LB10: =GO10+HY10+JI10+KS10 -> 0 | LC10: =KW10-KZ10 -> 0 | LD10: =KX10-LA10 -> 0 | LE10: =KY10-LB10 -> 0
E11: MTV | I11: =G11*H11 -> 0 | L11: =J11*K11 -> 0 | M11: =G11-J11 -> 0 | N11: =H11-K11 -> 0 | O11: =I11-L11 -> 0 | R11: =P11*Q11 -> 0 | U11: =S11*T11 -> 0 | V11: =P11-S11 -> 0 | W11: =Q11-T11 -> 0 | X11: =R11-U11 -> 0 | AA11: =Y11*Z11 -> 0 | AD11: =AB11*AC11 -> 0 | AE11: =Y11-AB11 -> 0 | AF11: =Z11-AC11 -> 0 | AG11: =AA11-AD11 -> 0 | AH11: =G11+P11+Y11 -> 0 | AI11: =IF(AJ11,AJ11/AH11,0) -> 0 | AJ11: =I11+R11+AA11 -> 0 | AK11: =J11+S11+AB11 -> 0 | AL11: =IF(AM11,AM11/AK11,0) -> 0 | AM11: =L11+U11+AD11 -> 0 | AN11: =AH11-AK11 -> 0 | AO11: =AI11-AL11 -> 0 | AP11: =AJ11-AM11 -> 0 | AS11: =AQ11*AR11 -> 0 | AV11: =AT11*AU11 -> 0 | AW11: =AQ11-AT11 -> 0 | AX11: =AR11-AU11 -> 0 | AY11: =AS11-AV11 -> 0 | BB11: =AZ11*BA11 -> 0 | BE11: =BC11*BD11 -> 0 | BF11: =AZ11-BC11 -> 0 | BG11: =BA11-BD11 -> 0 | BH11: =BB11-BE11 -> 0 | BK11: =BI11*BJ11 -> 0 | BN11: =BL11*BM11 -> 0 | BO11: =BI11-BL11 -> 0 | BP11: =BJ11-BM11 -> 0 | BQ11: =BK11-BN11 -> 0 | BR11: =AQ11+AZ11+BI11 -> 0 | BS11: =IF(BT11,BT11/BR11,0) -> 0 | BT11: =AS11+BB11+BK11 -> 0 | BU11: =AT11+BC11+BL11 -> 0 | BV11: =IF(BW11,BW11/BU11,0) -> 0 | BW11: =AV11+BE11+BN11 -> 0 | BX11: =BR11-BU11 -> 0 | BY11: =BS11-BV11 -> 0 | BZ11: =BT11-BW11 -> 0 | CC11: =CA11*CB11 -> 0 | CF11: =CD11*CE11 -> 0 | CG11: =CA11-CD11 -> 0 | CH11: =CB11-CE11 -> 0 | CI11: =CC11-CF11 -> 0 | CL11: =CJ11*CK11 -> 0 | CO11: =CM11*CN11 -> 0 | CP11: =CJ11-CM11 -> 0 | CQ11: =CK11-CN11 -> 0 | CR11: =CL11-CO11 -> 0 | CU11: =CS11*CT11 -> 0 | CX11: =CV11*CW11 -> 0 | CY11: =CS11-CV11 -> 0 | CZ11: =CT11-CW11 -> 0 | DA11: =CU11-CX11 -> 0 | DB11: =CA11+CJ11+CS11 -> 0 | DC11: =IF(DD11,DD11/DB11,0) -> 0 | DD11: =CC11+CL11+CU11 -> 0 | DE11: =CD11+CM11+CV11 -> 0 | DF11: =IF(DG11,DG11/DE11,0) -> 0 | DG11: =CF11+CO11+CX11 -> 0 | DH11: =DB11-DE11 -> 0 | DI11: =DC11-DF11 -> 0 | DJ11: =DD11-DG11 -> 0 | DM11: =DK11*DL11 -> 0 | DP11: =DN11*DO11 -> 0 | DQ11: =DK11-DN11 -> 0 | DR11: =DL11-DO11 -> 0 | DS11: =DM11-DP11 -> 0 | DV11: =DT11*DU11 -> 0 | DY11: =DW11*DX11 -> 0 | DZ11: =DT11-DW11 -> 0 | EA11: =DU11-DX11 -> 0 | EB11: =DV11-DY11 -> 0 | EE11: =EC11*ED11 -> 0 | EH11: =EF11*EG11 -> 0 | EI11: =EC11-EF11 -> 0 | EJ11: =ED11-EG11 -> 0 | EK11: =EE11-EH11 -> 0 | EL11: =DK11+DT11+EC11 -> 0 | EM11: =IF(EN11,EN11/EL11,0) -> 0 | EN11: =DM11+DV11+EE11 -> 0 | EO11: =DN11+DW11+EF11 -> 0 | EP11: =IF(EQ11,EQ11/EO11,0) -> 0 | EQ11: =DP11+DY11+EH11 -> 0 | ER11: =EL11-EO11 -> 0 | ES11: =EM11-EP11 -> 0 | ET11: =EN11-EQ11 -> 0 | EU11: =AH11+BR11+DB11+EL11 -> 0 | EV11: =IF(EW11,EW11/EU11,0) -> 0 | EW11: =AJ11+BT11+DD11+EN11 -> 0 | EX11: =AK11+BU11+DE11+EO11 -> 0 | EY11: =IF(EZ11,EZ11/EX11,0) -> 0 | EZ11: =AM11+BW11+DG11+EQ11 -> 0 | FA11: =EU11-EX11 -> 0 | FB11: =EV11-EY11 -> 0 | FC11: =EW11-EZ11 -> 0 | FK11: =FI11*FJ11 -> 0 | FN11: =FL11*FM11 -> 0 | FO11: =FI11-FL11 -> 0 | FP11: =FJ11-FM11 -> 0 | FQ11: =FK11-FN11 -> 0 | FT11: =FR11*FS11 -> 0 | FW11: =FU11*FV11 -> 0 | FX11: =FR11-FU11 -> 0 | FY11: =FS11-FV11 -> 0 | FZ11: =FT11-FW11 -> 0 | GC11: =GA11*GB11 -> 0 | GF11: =GD11*GE11 -> 0 | GG11: =GA11-GD11 -> 0 | GH11: =GB11-GE11 -> 0 | GI11: =GC11-GF11 -> 0 | GJ11: =FI11+FR11+GA11 -> 0 | GK11: =IF(GL11,GL11/GJ11,0) -> 0 | GL11: =FK11+FT11+GC11 -> 0 | GM11: =FL11+FU11+GD11 -> 0 | GN11: =IF(GO11,GO11/GM11,0) -> 0 | GO11: =FN11+FW11+GF11 -> 0 | GP11: =GJ11-GM11 -> 0 | GQ11: =GK11-GN11 -> 0 | GR11: =GL11-GO11 -> 0 | GU11: =GS11*GT11 -> 0 | GX11: =GV11*GW11 -> 0 | GY11: =GS11-GV11 -> 0 | GZ11: =GT11-GW11 -> 0 | HA11: =GU11-GX11 -> 0 | HD11: =HB11*HC11 -> 0 | HG11: =HE11*HF11 -> 0 | HH11: =HB11-HE11 -> 0 | HI11: =HC11-HF11 -> 0 | HJ11: =HD11-HG11 -> 0 | HM11: =HK11*HL11 -> 0 | HP11: =HN11*HO11 -> 0 | HQ11: =HK11-HN11 -> 0 | HR11: =HL11-HO11 -> 0 | HS11: =HM11-HP11 -> 0 | HT11: =GS11+HB11+HK11 -> 0 | HU11: =IF(HV11,HV11/HT11,0) -> 0 | HV11: =GU11+HD11+HM11 -> 0 | HW11: =GV11+HE11+HN11 -> 0 | HX11: =IF(HY11,HY11/HW11,0) -> 0 | HY11: =GX11+HG11+HP11 -> 0 | HZ11: =HT11-HW11 -> 0 | IA11: =HU11-HX11 -> 0 | IB11: =HV11-HY11 -> 0 | IE11: =IC11*ID11 -> 0 | IH11: =IF11*IG11 -> 0 | II11: =IC11-IF11 -> 0 | IJ11: =ID11-IG11 -> 0 | IK11: =IE11-IH11 -> 0 | IN11: =IL11*IM11 -> 0 | IQ11: =IO11*IP11 -> 0 | IR11: =IL11-IO11 -> 0 | IS11: =IM11-IP11 -> 0 | IT11: =IN11-IQ11 -> 0 | IW11: =IU11*IV11 -> 0 | IZ11: =IX11*IY11 -> 0 | JA11: =IU11-IX11 -> 0 | JB11: =IV11-IY11 -> 0 | JC11: =IW11-IZ11 -> 0 | JD11: =IC11+IL11+IU11 -> 0 | JE11: =IF(JF11,JF11/JD11,0) -> 0 | JF11: =IE11+IN11+IW11 -> 0 | JG11: =IF11+IO11+IX11 -> 0 | JH11: =IF(JI11,JI11/JG11,0) -> 0 | JI11: =IH11+IQ11+IZ11 -> 0 | JJ11: =JD11-JG11 -> 0 | JK11: =JE11-JH11 -> 0 | JL11: =JF11-JI11 -> 0 | JO11: =JM11*JN11 -> 0 | JR11: =JP11*JQ11 -> 0 | JS11: =JM11-JP11 -> 0 | JT11: =JN11-JQ11 -> 0 | JU11: =JO11-JR11 -> 0 | JX11: =JV11*JW11 -> 0 | KA11: =JY11*JZ11 -> 0 | KB11: =JV11-JY11 -> 0 | KC11: =JW11-JZ11 -> 0 | KD11: =JX11-KA11 -> 0 | KG11: =KE11*KF11 -> 0 | KJ11: =KH11*KI11 -> 0 | KK11: =KE11-KH11 -> 0 | KL11: =KF11-KI11 -> 0 | KM11: =KG11-KJ11 -> 0 | KN11: =JM11+JV11+KE11 -> 0 | KO11: =IF(KP11,KP11/KN11,0) -> 0 | KP11: =JO11+JX11+KG11 -> 0 | KQ11: =JP11+JY11+KH11 -> 0 | KR11: =IF(KS11,KS11/KQ11,0) -> 0 | KS11: =JR11+KA11+KJ11 -> 0 | KT11: =KN11-KQ11 -> 0 | KU11: =KO11-KR11 -> 0 | KV11: =KP11-KS11 -> 0 | KW11: =GJ11+HT11+JD11+KN11 -> 0 | KX11: =IF(KY11,KY11/KW11,0) -> 0 | KY11: =GL11+HV11+JF11+KP11 -> 0 | KZ11: =GM11+HW11+JG11+KQ11 -> 0 | LA11: =IF(LB11,LB11/KZ11,0) -> 0 | LB11: =GO11+HY11+JI11+KS11 -> 0 | LC11: =KW11-KZ11 -> 0 | LD11: =KX11-LA11 -> 0 | LE11: =KY11-LB11 -> 0
E12: MTV | I12: =G12*H12 -> 0 | L12: =J12*K12 -> 0 | M12: =G12-J12 -> 0 | N12: =H12-K12 -> 0 | O12: =I12-L12 -> 0 | R12: =P12*Q12 -> 0 | U12: =S12*T12 -> 0 | V12: =P12-S12 -> 0 | W12: =Q12-T12 -> 0 | X12: =R12-U12 -> 0 | AA12: =Y12*Z12 -> 0 | AD12: =AB12*AC12 -> 0 | AE12: =Y12-AB12 -> 0 | AF12: =Z12-AC12 -> 0 | AG12: =AA12-AD12 -> 0 | AH12: =G12+P12+Y12 -> 0 | AI12: =IF(AJ12,AJ12/AH12,0) -> 0 | AJ12: =I12+R12+AA12 -> 0 | AK12: =J12+S12+AB12 -> 0 | AL12: =IF(AM12,AM12/AK12,0) -> 0 | AM12: =L12+U12+AD12 -> 0 | AN12: =AH12-AK12 -> 0 | AO12: =AI12-AL12 -> 0 | AP12: =AJ12-AM12 -> 0 | AS12: =AQ12*AR12 -> 0 | AV12: =AT12*AU12 -> 0 | AW12: =AQ12-AT12 -> 0 | AX12: =AR12-AU12 -> 0 | AY12: =AS12-AV12 -> 0 | BB12: =AZ12*BA12 -> 0 | BE12: =BC12*BD12 -> 0 | BF12: =AZ12-BC12 -> 0 | BG12: =BA12-BD12 -> 0 | BH12: =BB12-BE12 -> 0 | BK12: =BI12*BJ12 -> 0 | BN12: =BL12*BM12 -> 0 | BO12: =BI12-BL12 -> 0 | BP12: =BJ12-BM12 -> 0 | BQ12: =BK12-BN12 -> 0 | BR12: =AQ12+AZ12+BI12 -> 0 | BS12: =IF(BT12,BT12/BR12,0) -> 0 | BT12: =AS12+BB12+BK12 -> 0 | BU12: =AT12+BC12+BL12 -> 0 | BV12: =IF(BW12,BW12/BU12,0) -> 0 | BW12: =AV12+BE12+BN12 -> 0 | BX12: =BR12-BU12 -> 0 | BY12: =BS12-BV12 -> 0 | BZ12: =BT12-BW12 -> 0 | CC12: =CA12*CB12 -> 0 | CF12: =CD12*CE12 -> 0 | CG12: =CA12-CD12 -> 0 | CH12: =CB12-CE12 -> 0 | CI12: =CC12-CF12 -> 0 | CL12: =CJ12*CK12 -> 0 | CO12: =CM12*CN12 -> 0 | CP12: =CJ12-CM12 -> 0 | CQ12: =CK12-CN12 -> 0 | CR12: =CL12-CO12 -> 0 | CU12: =CS12*CT12 -> 0 | CX12: =CV12*CW12 -> 0 | CY12: =CS12-CV12 -> 0 | CZ12: =CT12-CW12 -> 0 | DA12: =CU12-CX12 -> 0 | DB12: =CA12+CJ12+CS12 -> 0 | DC12: =IF(DD12,DD12/DB12,0) -> 0 | DD12: =CC12+CL12+CU12 -> 0 | DE12: =CD12+CM12+CV12 -> 0 | DF12: =IF(DG12,DG12/DE12,0) -> 0 | DG12: =CF12+CO12+CX12 -> 0 | DH12: =DB12-DE12 -> 0 | DI12: =DC12-DF12 -> 0 | DJ12: =DD12-DG12 -> 0 | DM12: =DK12*DL12 -> 0 | DP12: =DN12*DO12 -> 0 | DQ12: =DK12-DN12 -> 0 | DR12: =DL12-DO12 -> 0 | DS12: =DM12-DP12 -> 0 | DV12: =DT12*DU12 -> 0 | DY12: =DW12*DX12 -> 0 | DZ12: =DT12-DW12 -> 0 | EA12: =DU12-DX12 -> 0 | EB12: =DV12-DY12 -> 0 | EE12: =EC12*ED12 -> 0 | EH12: =EF12*EG12 -> 0 | EI12: =EC12-EF12 -> 0 | EJ12: =ED12-EG12 -> 0 | EK12: =EE12-EH12 -> 0 | EL12: =DK12+DT12+EC12 -> 0 | EM12: =IF(EN12,EN12/EL12,0) -> 0 | EN12: =DM12+DV12+EE12 -> 0 | EO12: =DN12+DW12+EF12 -> 0 | EP12: =IF(EQ12,EQ12/EO12,0) -> 0 | EQ12: =DP12+DY12+EH12 -> 0 | ER12: =EL12-EO12 -> 0 | ES12: =EM12-EP12 -> 0 | ET12: =EN12-EQ12 -> 0 | EU12: =AH12+BR12+DB12+EL12 -> 0 | EV12: =IF(EW12,EW12/EU12,0) -> 0 | EW12: =AJ12+BT12+DD12+EN12 -> 0 | EX12: =AK12+BU12+DE12+EO12 -> 0 | EY12: =IF(EZ12,EZ12/EX12,0) -> 0 | EZ12: =AM12+BW12+DG12+EQ12 -> 0 | FA12: =EU12-EX12 -> 0 | FB12: =EV12-EY12 -> 0 | FC12: =EW12-EZ12 -> 0 | FK12: =FI12*FJ12 -> 0 | FN12: =FL12*FM12 -> 0 | FO12: =FI12-FL12 -> 0 | FP12: =FJ12-FM12 -> 0 | FQ12: =FK12-FN12 -> 0 | FT12: =FR12*FS12 -> 0 | FW12: =FU12*FV12 -> 0 | FX12: =FR12-FU12 -> 0 | FY12: =FS12-FV12 -> 0 | FZ12: =FT12-FW12 -> 0 | GC12: =GA12*GB12 -> 0 | GF12: =GD12*GE12 -> 0 | GG12: =GA12-GD12 -> 0 | GH12: =GB12-GE12 -> 0 | GI12: =GC12-GF12 -> 0 | GJ12: =FI12+FR12+GA12 -> 0 | GK12: =IF(GL12,GL12/GJ12,0) -> 0 | GL12: =FK12+FT12+GC12 -> 0 | GM12: =FL12+FU12+GD12 -> 0 | GN12: =IF(GO12,GO12/GM12,0) -> 0 | GO12: =FN12+FW12+GF12 -> 0 | GP12: =GJ12-GM12 -> 0 | GQ12: =GK12-GN12 -> 0 | GR12: =GL12-GO12 -> 0 | GU12: =GS12*GT12 -> 0 | GX12: =GV12*GW12 -> 0 | GY12: =GS12-GV12 -> 0 | GZ12: =GT12-GW12 -> 0 | HA12: =GU12-GX12 -> 0 | HD12: =HB12*HC12 -> 0 | HG12: =HE12*HF12 -> 0 | HH12: =HB12-HE12 -> 0 | HI12: =HC12-HF12 -> 0 | HJ12: =HD12-HG12 -> 0 | HM12: =HK12*HL12 -> 0 | HP12: =HN12*HO12 -> 0 | HQ12: =HK12-HN12 -> 0 | HR12: =HL12-HO12 -> 0 | HS12: =HM12-HP12 -> 0 | HT12: =GS12+HB12+HK12 -> 0 | HU12: =IF(HV12,HV12/HT12,0) -> 0 | HV12: =GU12+HD12+HM12 -> 0 | HW12: =GV12+HE12+HN12 -> 0 | HX12: =IF(HY12,HY12/HW12,0) -> 0 | HY12: =GX12+HG12+HP12 -> 0 | HZ12: =HT12-HW12 -> 0 | IA12: =HU12-HX12 -> 0 | IB12: =HV12-HY12 -> 0 | IE12: =IC12*ID12 -> 0 | IH12: =IF12*IG12 -> 0 | II12: =IC12-IF12 -> 0 | IJ12: =ID12-IG12 -> 0 | IK12: =IE12-IH12 -> 0 | IN12: =IL12*IM12 -> 0 | IQ12: =IO12*IP12 -> 0 | IR12: =IL12-IO12 -> 0 | IS12: =IM12-IP12 -> 0 | IT12: =IN12-IQ12 -> 0 | IW12: =IU12*IV12 -> 0 | IZ12: =IX12*IY12 -> 0 | JA12: =IU12-IX12 -> 0 | JB12: =IV12-IY12 -> 0 | JC12: =IW12-IZ12 -> 0 | JD12: =IC12+IL12+IU12 -> 0 | JE12: =IF(JF12,JF12/JD12,0) -> 0 | JF12: =IE12+IN12+IW12 -> 0 | JG12: =IF12+IO12+IX12 -> 0 | JH12: =IF(JI12,JI12/JG12,0) -> 0 | JI12: =IH12+IQ12+IZ12 -> 0 | JJ12: =JD12-JG12 -> 0 | JK12: =JE12-JH12 -> 0 | JL12: =JF12-JI12 -> 0 | JO12: =JM12*JN12 -> 0 | JR12: =JP12*JQ12 -> 0 | JS12: =JM12-JP12 -> 0 | JT12: =JN12-JQ12 -> 0 | JU12: =JO12-JR12 -> 0 | JX12: =JV12*JW12 -> 0 | KA12: =JY12*JZ12 -> 0 | KB12: =JV12-JY12 -> 0 | KC12: =JW12-JZ12 -> 0 | KD12: =JX12-KA12 -> 0 | KG12: =KE12*KF12 -> 0 | KJ12: =KH12*KI12 -> 0 | KK12: =KE12-KH12 -> 0 | KL12: =KF12-KI12 -> 0 | KM12: =KG12-KJ12 -> 0 | KN12: =JM12+JV12+KE12 -> 0 | KO12: =IF(KP12,KP12/KN12,0) -> 0 | KP12: =JO12+JX12+KG12 -> 0 | KQ12: =JP12+JY12+KH12 -> 0 | KR12: =IF(KS12,KS12/KQ12,0) -> 0 | KS12: =JR12+KA12+KJ12 -> 0 | KT12: =KN12-KQ12 -> 0 | KU12: =KO12-KR12 -> 0 | KV12: =KP12-KS12 -> 0 | KW12: =GJ12+HT12+JD12+KN12 -> 0 | KX12: =IF(KY12,KY12/KW12,0) -> 0 | KY12: =GL12+HV12+JF12+KP12 -> 0 | KZ12: =GM12+HW12+JG12+KQ12 -> 0 | LA12: =IF(LB12,LB12/KZ12,0) -> 0 | LB12: =GO12+HY12+JI12+KS12 -> 0 | LC12: =KW12-KZ12 -> 0 | LD12: =KX12-LA12 -> 0 | LE12: =KY12-LB12 -> 0
